Workbook

Sheet Сводка и Ответы
B2: ИТОГОВАЯ СВОДКА РАСЧЕТОВ НАДЕЖНОСТИ (ПРАКТИКА № 4)
B3: Сводная ведомость результатов по всем задачам с постоянным резервированием
B4: Студент: Гайнанов Дамир Ильдарович | Группа: ЭАС-414С
B6: Студент: | D6: Гайнанов Дамир Ильдарович
B7: Группа / Факультет: | D7: ЭАС-414С / Кафедра ЭАПП
B8: Дисциплина: | D8: Надежность автоматизированных систем (НАС)
B9: Тема практической работы: | D9: Расчет надежности системы с постоянным резервированием (Слайды 19-28)
B11: № | C11: Наименование задачи / Объекта | D11: Определяемый показатель | E11: Формула в Excel | F11: Результат | G11: Ед. изм. | H11: Статус
B12: № 4 | C12: Трехблочная система (резерв отсутствует) | D12: Pc_нр(100) | E12: ='Задачи 4-14'!E14 | F12: — | G12: Рассчитано
B13: № 4 | C13: Трехблочная система (общее дублирование) | D13: Pc_дубл(100) | E13: ='Задачи 4-14'!E15 | F13: — | G13: Рассчитано
B14: № 5 | C14: Логическая схема 4.3 (вероятность при t=100 ч) | D14: Pc(100) | E14: ='Задачи 4-14'!E28 | F14: — | G14: Рассчитано
B15: № 5 | C15: Логическая схема 4.3 (средняя наработка) | D15: mtc | E15: ='Задачи 4-14'!E29 | F15: ч | G15: Рассчитано
B16: № 6 | C16: Радиопередатчик (дублирование, наработка mtc) | D16: mtc | E16: ='Задачи 4-14'!E42 | F16: ч | G16: Рассчитано
B17: № 6 | C17: Радиопередатчик (вероятность при t=100 ч) | D17: Pc(100) | E17: ='Задачи 4-14'!E43 | F17: — | G17: Рассчитано
B18: № 7 | C18: Схема дублирования цепи 4.4 (наработка mtc) | D18: mtc | E18: ='Задачи 4-14'!E56 | F18: ч | G18: Рассчитано
B19: № 7 | C19: Схема дублирования цепи 4.4 (интенсивность при t=100) | D19: λc(100) | E19: ='Задачи 4-14'!E58 | F19: 1/ч | G19: Рассчитано
B20: № 8 | C20: Трехблочная система (без резерва) | D20: Pc_нр(100) | E20: ='Задачи 4-14'!E70 | F20: — | G20: Рассчитано
B21: № 8 | C21: Трехблочная система (общее дублирование) | D21: Pc_дубл(100) | E21: ='Задачи 4-14'!E71 | F21: — | G21: Рассчитано
B22: № 9 | C22: Тройное резервирование ветвей 4.5 (вероятность t=100) | D22: Pc(100) | E22: ='Задачи 4-14'!E84 | F22: — | G22: Рассчитано
B23: № 9 | C23: Тройное резервирование ветвей 4.5 (наработка mtc) | D23: mtc | E23: ='Задачи 4-14'!E85 | F23: ч | G23: Рассчитано
B24: № 9 | C24: Тройное резервирование ветвей 4.5 (интенсивность λc) | D24: λc(100) | E24: ='Задачи 4-14'!E87 | F24: 1/ч | G24: Рассчитано
B25: № 10 | C25: Телевизионный канал (наработка mtc) | D25: mtc | E25: ='Задачи 4-14'!E98 | F25: ч | G25: Рассчитано
B26: № 10 | C26: Телевизионный канал (вероятность при t=50 ч) | D26: Pc(50) | E26: ='Задачи 4-14'!E99 | F26: — | G26: Рассчитано
B27: № 11 | C27: Дублированная цепь двух элементов (интенсивность λc) | D27: λc(50) | E27: ='Задачи 4-14'!E112 | F27: 1/ч | G27: Рассчитано
B28: № 12 | C28: Система n=4000 (допустимая λдоп без резерва) | D28: λдоп_а | E28: ='Задачи 4-14'!E124 | F28: 1/ч | G28: Рассчитано
B29: № 12 | C29: Система n=4000 (допустимая λдоп с дублированием) | D29: λдоп_б | E29: ='Задачи 4-14'!E126 | F29: 1/ч | G29: Рассчитано
B30: № 13 | C30: Требуемая надежность блока: а) без резерва | D30: Pбл_а | E30: ='Задачи 4-14'!E136 | F30: — | G30: Рассчитано
B31: № 13 | C31: Требуемая надежность блока: б) общее дублирование | D31: Pбл_б | E31: ='Задачи 4-14'!E138 | F31: — | G31: Рассчитано
B32: № 13 | C32: Требуемая надежность блока: в) раздельное дублирование | D32: Pбл_в | E32: ='Задачи 4-14'!E140 | F32: — | G32: Рассчитано
B33: № 14 | C33: Вычислитель (вероятность при t=20 ч) | D33: Pc(20) | E33: ='Задачи 4-14'!E152 | F33: — | G33: Рассчитано
B34: № 14 | C34: Вычислитель (средняя наработка mtc) | D34: mtc | E34: ='Задачи 4-14'!E151 | F34: ч | G34: Рассчитано

Sheet Задачи 4-14
B2: ЗАДАЧИ ДЛЯ САМОСТОЯТЕЛЬНОГО РЕШЕНИЯ (№ 4 – 14)
B3: Практическая работа № 4. Расчет надежности системы с постоянным резервированием
B4: Все расчеты выполнены динамическими формулами Excel со ссылками на исходные параметры
B6: ЗАДАЧА № 4. СРАВНЕНИЕ СИСТЕМЫ БЕЗ РЕЗЕРВА И С ОБЩИМ ДУБЛИРОВАНИЕМ
B7: Условие: Технологическая система состоит из 3 блоков: Б1, Б2, Б3 с интенсивностями λ1=4*10^-4, λ2=2.5*10^-4, λ3=3*10^-4 1/ч. Рассчитать вероятность безотказной работы системы при t=100 ч для: а) резерв отсутствует; б) имеется общее дублирование системы в целом.
B8: Параметр / Величина | C8: Обозначение | D8: Формула / Источник | E8: Значение | F8: Ед. изм. | G8: Примечание
B9: Интенсивность отказов блока 1 | C9: λ1 | D9: Дано | E9: 0.0004 | F9: 1/ч | G9: Блок Б1 (4.0*10^-4)
B10: Интенсивность отказов блока 2 | C10: λ2 | D10: Дано | E10: 0.00025 | F10: 1/ч | G10: Блок Б2 (2.5*10^-4)
B11: Интенсивность отказов блока 3 | C11: λ3 | D11: Дано | E11: 0.0003 | F11: 1/ч | G11: Блок Б3 (3.0*10^-4)
B12: Время работы системы | C12: t | D12: Дано | E12: 100 | F12: ч | G12: Контрольная наработка
B13: Суммарная интенсивность цепи | C13: λ0 | D13: λ1 + λ2 + λ3 | E13: =E9+E10+E11 | F13: 1/ч | G13: Интенсивность цепи без резерва
B14: а) Вероятность без резерва | C14: Pc_нр | D14: EXP(-λ0 * t) | E14: =EXP(-E13*E12) | F14: — | G14: Экспоненциальный закон цепи
B15: б) Вероятность при общем дублировании | C15: Pc_дубл | D15: 1 - (1 - EXP(-λ0*t))^2 | E15: =1-(1-EXP(-E13*E12))^2 | F15: — | G15: Постоянный нагруженный резерв (m=1)
B16: Выигрыш по надежности | C16: ΔPc | D16: Pc_дубл - Pc_нр | E16: =E15-E14 | F16: — | G16: Абсолютный прирост вероятности
B17: Вывод: Общее дублирование повышает вероятность безотказной работы с 90.94% до 99.18% (прирост +8.24%).
B20: ЗАДАЧА № 5. АНАЛИЗ ЛОГИЧЕСКОЙ СХЕМЫ С РЕЗЕРВИРОВАННОЙ ЧАСТЬЮ (РИС. 4.3)
B21: Условие: Для логической схемы на рис. 4.3 определить Pc(t), mtc, fc(t), λc(t). Часть I: две параллельные ветви по 4 последовательных блока λ. Часть II: последовательно включен 1 блок λ. Резерв нагруженный, отказы независимы.
B22: Параметр / Величина | C22: Обозначение | D22: Формула / Источник | E22: Значение | F22: Ед. изм. | G22: Примечание
B23: Число блоков в параллельной ветви | C23: n_ветвь | D23: Рис. 4.3 | E23: 4 | F23: шт. | G23: 4 блока в каждой из двух ветвей
B24: Кратность резервирования части I | C24: m | D24: Рис. 4.3 | E24: 1 | F24: — | G24: Дублирование ветви из 4 блоков
B25: Интенсивность отказов блока (базовая) | C25: λ | D25: Принято | E25: 0.0001 | F25: 1/ч | G25: Для численной оценки (1.0*10^-4)
B26: Время оценки | C26: t | D26: Принято | E26: 100 | F26: ч | G26: Контрольная наработка
B27: Интенсивность одной ветви | C27: λ_в | D27: 4 * λ | E27: =4*E25 | F27: 1/ч | G27: Цепь из 4 последовательных блоков
B28: Вероятность системы Pc(t) | C28: Pc(t) | D28: 2*EXP(-5*λ*t) - EXP(-9*λ*t) | E28: =2*EXP(-5*E25*E26)-EXP(-9*E25*E26) | F28: — | G28: Pc(t) = (2e^-4λt - e^-8λt)*e^-λt
B29: Средняя наработка до отказа mtc | C29: mtc | D29: 13 / (45 * λ) | E29: =13/(45*E25) | F29: ч | G29: mtc = 2/(5λ) - 1/(9λ) = 13/(45λ)
B30: Частота отказов системы fc(t) | C30: fc(t) | D30: 10*λ*EXP(-5*λ*t) - 9*λ*EXP(-9*λ*t) | E30: =10*E25*EXP(-5*E25*E26)-9*E25*EXP(-9*E25*E26) | F30: 1/ч | G30: fc(t) = -dPc(t)/dt
B31: Интенсивность отказов системы λc(t) | C31: λc(t) | D31: fc(t) / Pc(t) | E31: =E30/E28 | F31: 1/ч | G31: λc(t) = λ*(10 - 9e^-4λt)/(2 - e^-4λt)
B32: Вывод: Аналитические выражения: Pc(t) = 2e^-5λt - e^-9λt; mtc = 13/(45λ); fc(t) = 10λe^-5λt - 9λe^-9λt; λc(t) = λ(10-9e^-4λt)/(2-e^-4λt).
B35: ЗАДАЧА № 6. ОБЩЕЕ ПОСТОЯННОЕ ДУБЛИРОВАНИЕ РАДИОПЕРЕДАТЧИКА (n = 3)
B36: Условие: В радиопередатчике из 3 равнонадежных каскадов (n=3) применено общее постоянное дублирование. Интенсивность каскада λ=5*10^-4 1/ч. Определить Pc(t), mtc, fc(t), λc(t) радиопередатчика с дублированием.
B37: Параметр / Величина | C37: Обозначение | D37: Формула / Источник | E37: Значение | F37: Ед. изм. | G37: Примечание
B38: Число каскадов радиопередатчика | C38: n | D38: Дано | E38: 3 | F38: шт. | G38: Последовательные каскады
B39: Интенсивность отказов каскада | C39: λ | D39: Дано | E39: 0.0005 | F39: 1/ч | G39: λ = 5.0*10^-4 1/ч
B40: Контрольное время наработки | C40: t | D40: Принято | E40: 100 | F40: ч | G40: Контрольная наработка t = 100 ч
B41: Интенсивность цепи радиопередатчика | C41: λ0 | D41: n * λ | E41: =E38*E39 | F41: 1/ч | G41: λ0 = 3 * 0.0005 = 0.0015 1/ч
B42: Средняя наработка до отказа mtc | C42: mtc | D42: 1.5 / λ0 | E42: =1.5/E41 | F42: ч | G42: mtc = 1.5 * T0 = 1.5 / 0.0015
B43: Вероятность безотказной работы Pc(t) | C43: Pc(t) | D43: 1 - (1 - EXP(-λ0*t))^2 | E43: =1-(1-EXP(-E41*E40))^2 | F43: — | G43: Pc(t) = 2e^-λ0t - e^-2λ0t
B44: Частота отказов системы fc(t) | C44: fc(t) | D44: 2*λ0*EXP(-λ0*t)*(1-EXP(-λ0*t)) | E44: =2*E41*EXP(-E41*E40)*(1-EXP(-E41*E40)) | F44: 1/ч | G44: fc(t) = 0.003*e^-0.0015t*(1-e^-0.0015t)
B45: Интенсивность отказов системы λc(t) | C45: λc(t) | D45: fc(t) / Pc(t) | E45: =E44/E43 | F45: 1/ч | G45: λc(t) = 0.003*(1-e^-0.0015t)/(2-e^-0.0015t)
B46: Вывод: mtc = 1000 ч; аналитические зависимости: Pc(t) = 2e^-0.0015t - e^-0.003t; fc(t) = 0.003e^-0.0015t(1-e^-0.0015t). При t=100 ч Pc=0.9806.
...

Sheet Типовые задачи (№1-3)
B2: ТИПОВЫЕ ЗАДАЧИ С РЕШЕНИЕМ (№ 1 – 3)
B3: Практическая работа № 4. Раздел 4.2 презентации
B4: Методические примеры расчета резервированных систем
B6: ТИПОВАЯ ЗАДАЧА № 1. СРАВНЕНИЕ ХАРАКТЕРИСТИК ДУБЛИРОВАННОЙ И НЕБЕЗЕРВНОЙ СИСТЕМ
B7: Условие: Система состоит из n=10 равнонадежных элементов, mt=1000 ч. Экспоненциальный закон. Найти mtc, fc(50), λc(50) при t=50 ч для: а) нерезервированной системы; б) дублированной системы с постоянным резервом.
B8: Параметр / Величина | C8: Обозначение | D8: Формула / Источник | E8: Значение | F8: Ед. изм. | G8: Примечание
B9: Число элементов системы | C9: n | D9: Дано | E9: 10 | F9: шт. | G9: Равнонадежные элементы
B10: Средняя наработка элемента | C10: mt | D10: Дано | E10: 1000 | F10: ч | G10: mt = 1000 ч
B11: Контрольное время наработки | C11: t | D11: Дано | E11: 50 | F11: ч | G11: t = 50 ч
B12: Интенсивность отказа элемента | C12: λi | D12: 1 / mt | E12: =1/E10 | F12: 1/ч | G12: λi = 1/1000 = 0.001 1/ч
B13: Интенсивность нерезервированной цепи | C13: λ0 | D13: n * λi | E13: =E9*E12 | F13: 1/ч | G13: λ0 = 10 * 0.001 = 0.01 1/ч
B14: а) Наработка без резерва mtc_а | C14: mtc_а | D14: 1 / λ0 | E14: =1/E13 | F14: ч | G14: mtc = 1 / 0.01 = 100 ч
B15: а) Вероятность без резерва Pc_а(50) | C15: Pc_а(50) | D15: EXP(-λ0 * t) | E15: =EXP(-E13*E11) | F15: — | G15: Pc(50) = e^-0.5 ≈ 0.60653
B16: а) Частота отказов без резерва fc_а(50) | C16: fc_а(50) | D16: λ0 * Pc_а | E16: =E13*E15 | F16: 1/ч | G16: fc(50) = λ0 * Pc(50) ≈ 0.006065
B17: а) Интенсивность без резерва λc_а(50) | C17: λc_а(50) | D17: λ0 | E17: =E13 | F17: 1/ч | G17: λc(t) = const = 0.01 1/ч
B18: б) Наработка дублированной mtc_б | C18: mtc_б | D18: 1.5 / λ0 | E18: =1.5/E13 | F18: ч | G18: mtc = 1.5 * 100 = 150 ч
B19: б) Вероятность дублированной Pc_б(50) | C19: Pc_б(50) | D19: 1 - (1 - EXP(-λ0*t))^2 | E19: =1-(1-EXP(-E13*E11))^2 | F19: — | G19: Pc(50) = 2e^-0.5 - e^-1.0 ≈ 0.84518
B20: б) Частота отказов дублированной fc_б(50) | C20: fc_б(50) | D20: 2*λ0*EXP(-λ0*t)*(1-EXP(-λ0*t)) | E20: =2*E13*EXP(-E13*E11)*(1-EXP(-E13*E11)) | F20: 1/ч | G20: fc(50) ≈ 0.004773 1/ч
B21: б) Интенсивность дублированной λc_б(50) | C21: λc_б(50) | D21: fc_б / Pc_б | E21: =E20/E19 | F21: 1/ч | G21: λc(50) ≈ 0.005647 1/ч
B22: Вывод: При дублировании средняя наработка возрастает в 1.5 раза (со 100 до 150 ч), а вероятность возрастает с 0.6065 до 0.8452.
B25: ТИПОВАЯ ЗАДАЧА № 2. ДУБЛИРОВАНИЕ КАНАЛА УПРАВЛЕНИЯ
B26: Условие: В технологической системе применено дублирование канала управления (m=1, n=1). Интенсивность отказов канала λ=10^-2 1/ч. Рассчитать Pc(10), mtc, fc(10), λc(10) при t=10 ч.
B27: Параметр / Величина | C27: Обозначение | D27: Формула / Источник | E27: Значение | F27: Ед. изм. | G27: Примечание
B28: Интенсивность отказов канала | C28: λ | D28: Дано | E28: 0.01 | F28: 1/ч | G28: λ = 10^-2 = 0.01 1/ч
B29: Время оценки | C29: t | D29: Дано | E29: 10 | F29: ч | G29: Контрольная точка t = 10 ч
B30: Вероятность безотказной работы Pc(10) | C30: Pc(10) | D30: 1 - (1 - EXP(-λ*t))^2 | E30: =1-(1-EXP(-E28*E29))^2 | F30: — | G30: Pc(10) = 1 - (1 - e^-0.1)^2 ≈ 0.99094
B31: Средняя наработка до отказа mtc | C31: mtc | D31: 1.5 / λ | E31: =1.5/E28 | F31: ч | G31: mtc = 1.5 / 0.01 = 150 ч
B32: Частота отказов fc(10) | C32: fc(10) | D32: 2*λ*EXP(-λ*t)*(1-EXP(-λ*t)) | E32: =2*E28*EXP(-E28*E29)*(1-EXP(-E28*E29)) | F32: 1/ч | G32: fc(10) = 0.02*e^-0.1*(1-e^-0.1) ≈ 0.001722
B33: Интенсивность отказов λc(10) | C33: λc(10) | D33: fc(10) / Pc(10) | E33: =E32/E30 | F33: 1/ч | G33: λc(10) ≈ 0.001738 1/ч
B34: Вывод: При t=10 ч: Pc=0.99094 (в слайде ≈0.99), mtc=150 ч, fc=0.001722 1/ч, λc=0.001738 1/ч.
B37: ТИПОВАЯ ЗАДАЧА № 3. ОЦЕНКА ДОПУСТИМОЙ ИНТЕНСИВНОСТИ ЭЛЕМЕНТА ПРИ ДУБЛИРОВАНИИ
B38: Условие: Нерезервированная система состоит из n=5000 элементов. Предполагается провести общее дублирование. Оценить требуемую среднюю интенсивность одного элемента при условии Pc(10)>=0.9 при t=10 ч.
B39: Параметр / Величина | C39: Обозначение | D39: Формула / Источник | E39: Значение | F39: Ед. изм. | G39: Примечание
B40: Число элементов | C40: n | D40: Дано | E40: 5000 | F40: шт. | G40: Объем системы
B41: Требуемая надежность системы | C41: Pc | D41: Дано | E41: 0.9 | F41: — | G41: Pc(10) >= 0.90
B42: Время наработки | C42: t | D42: Дано | E42: 10 | F42: ч | G42: t = 10 ч
B43: Требуемая надежность цепи Pцепь | C43: Pцепь | D43: 1 - SQRT(1 - Pc) | E43: =1-SQRT(1-E41) | F43: — | G43: Pцепь = 1 - sqrt(0.1) ≈ 0.683772
B44: Приближенное разложение (по слайду) | C44: λ_прибл | D44: SQRT(1 - Pc) / (n * t) | E44: =SQRT(1-E41)/(E40*E42) | F44: 1/ч | G44: λ <= (6.32*10^-5)/10 = 6.32*10^-6 1/ч
B45: Точное значение по экспоненте | C45: λ_точн | D45: -LN(Pцепь) / (n * t) | E45: =-LN(E43)/(E40*E42) | F45: 1/ч | G45: λ = -ln(0.683772)/(5000*10) = 7.60*10^-6 1/ч
B46: Вывод: По приближенной формуле слайда λ <= 6.32*10^-6 1/ч; по точной формуле экспоненциального закона λ <= 7.60*10^-6 1/ч.

Sheet Теория резервирования
B2: ТЕОРЕТИЧЕСКИЕ ОСНОВЫ РАСЧЕТА НАДЕЖНОСТИ СИСТЕМ С ПОСТОЯННЫМ РЕЗЕРВИРОВАНИЕМ
B3: Справочник формул, определений и математических соотношений (Раздел 4.1)
B4: Нормативно-техническая база расчета надежности резервированных автоматизированных систем
B6: 1. Понятие постоянного резервирования (нагруженного резерва)
B7: Определение | C7: Резервные элементы находятся в том же рабочем режиме, что и основной, включены параллельно постоянно в течение всего времени работы.
B8: Особенность | C8: При отказе элементов перестройка схемы не требуется, отказавший элемент не отключается, задержка включения равна нулю.
B9: Кратность резервирования m | C9: m = число резервных цепей/элементов. Общее число параллельных цепей равно k = m + 1.
B11: 2. Вероятность безотказной работы и отказа системы
B12: Вероятность отказа qc(t) | C12: qc(t) = Произведение(q_j(t)) = (1 - P(t))^(m+1) при равнонадежных цепях.
B13: Вероятность безотказной работы Pc(t) | C13: Pc(t) = 1 - qc(t) = 1 - [1 - P(t)]^(m+1). При дублировании (m=1): Pc(t) = 2*P(t) - P(t)^2.
B14: Экспоненциальный закон цепи | C14: Если P(t) = exp(-λ0*t), то Pc(t) = 2*exp(-λ0*t) - exp(-2*λ0*t).
B16: 3. Наработка на отказ, частота и интенсивность отказов дублированной системы
B17: Среднее время mtc | C17: mtc = 1.5 * T0 = 1.5 / λ0 (увеличение средней наработки на 50% по сравнению с нерезервированной цепью).
B18: В общем случае кратности m | C18: mtc = (1/λ0) * [1 + 1/2 + 1/3 + ... + 1/(m+1)]. При тройном резерве (m=2) mtc = (11/6)/λ0.
B19: Частота отказов fc(t) | C19: fc(t) = -dPc(t)/dt = 2*λ0*exp(-λ0*t)*[1 - exp(-λ0*t)]. При t=0 fc(0) = 0.
B20: Интенсивность отказов λc(t) | C20: λc(t) = fc(t) / Pc(t) = 2*λ0*[1 - exp(-λ0*t)] / [2 - exp(-λ0*t)]. При t=0 λc=0; при t->∞ λc->λ0.
B22: 4. Сравнение общего и раздельного резервирования
B23: Общее резервирование | C23: Резервируется вся система из n элементов целиком (дублируется цепочка из n блоков).
B24: Раздельное (поэлементное) | C24: Каждый отдельный блок системы дублируется независимо, затем дублированные группы соединяются последовательно.
B25: Теорема эффективности | C25: Раздельное резервирование всегда надежнее общего при одинаковом количестве резервных элементов.
