Workbook

Sheet Сводка и Ответы
B2: ПРАКТИЧЕСКАЯ РАБОТА № 3 — СВОДНЫЕ РЕЗУЛЬТАТЫ
B3: Последовательное соединение элементов в систему (расчет количественных характеристик надежности)
B4: Дисциплина: Надежность автоматизированных систем (НАС) | Преподаватель: Ризванов | Выполнил: Студент Гайнанов Д.И.
B6: 1. РЕЗУЛЬТАТЫ РЕШЕНИЯ ЗАДАЧ ДЛЯ САМОСТОЯТЕЛЬНОГО РЕШЕНИЯ (№ 8 – 13)
B7: № задачи | C7: Краткое условие задачи | D7: Определяемый показатель | E7: Математическая формула | F7: Результат вычислений | G7: Ед. изм. | H7: Ссылка на решение | I7: Статус
B8: Задача 8 | C8: n=2000, λср=0.33·10⁻⁵ ч⁻¹, t=200 ч. Найти Pc(200) | D8: Pc(200) | E8: Pc = exp(-n · λср · t) | F8: ='Задачи 8-13'!E19 | G8: — | H8: Смотреть | I8: Решено
B9: Задача 8 (2) | C9: Та же задача, средняя наработка системы mtc | D9: mtc | E9: mtc = 1 / (n · λср) | F9: ='Задачи 8-13'!E21 | G9: ч | H9: Смотреть | I9: Решено
B10: Задача 9 | C10: ЭВМ из 200000 элементов, λср=0.2·10⁻⁶ ч⁻¹, сутки (t=24 ч) | D10: Pc(24) | E10: Pc = exp(-n · λср · 24) | F10: ='Задачи 8-13'!E38 | G10: — | H10: Смотреть | I10: Решено
B11: Задача 9 (2) | C11: Та же задача, средняя наработка ЭВМ mtc | D11: mtc | E11: mtc = 1 / (n · λср) | F11: ='Задачи 8-13'!E40 | G11: ч | H11: Смотреть | I11: Решено
B12: Задача 10 | C12: n=6000, λср=0.16·10⁻⁶ ч⁻¹, t=50 ч. Найти Pc(50) | D12: Pc(50) | E12: Pc = exp(-n · λср · t) | F12: ='Задачи 8-13'!E57 | G12: — | H12: Смотреть | I12: Решено
B13: Задача 10 (2) | C13: Та же задача, средняя наработка системы mtc | D13: mtc | E13: mtc = 1 / (n · λср) | F13: ='Задачи 8-13'!E59 | G13: ч | H13: Смотреть | I13: Решено
B14: Задача 11 | C14: Прибор из 5 узлов (Pi = {0.98, 0.99, 0.998, 0.975, 0.985}) | D14: Pc (точная) | E14: Pc = Π Pi | F14: ='Задачи 8-13'!E76 | G14: — | H14: Смотреть | I14: Решено
B15: Задача 11 (2) | C15: Та же задача, приближенное значение по формуле (3.18) | D15: Pc (прибл.) | E15: Pc ≈ 1 - Σ(1 - Pi) | F15: ='Задачи 8-13'!E78 | G15: — | H15: Смотреть | I15: Решено
B16: Задача 12 | C16: Система из 5 приборов (mti = {83, 220, 280, 400, 700} ч) | D16: λc | E16: λc = Σ(1/mti) | F16: ='Задачи 8-13'!F93 | G16: 1/ч | H16: Смотреть | I16: Решено
B17: Задача 12 (2) | C17: Та же задача, средняя наработка системы mtc | D17: mtc | E17: mtc = 1 / λc | F17: ='Задачи 8-13'!E97 | G17: ч | H17: Смотреть | I17: Решено
B18: Задача 13 | C18: 5 блоков с Pi={0.98..0.985} за 50 ч. Найти mtc прибора | D18: mtc (точная) | E18: mtc = -t / ln(Pc) | F18: ='Задачи 8-13'!E117 | G18: ч | H18: Смотреть | I18: Решено
B19: Задача 13 (2) | C19: Та же задача, приближенное значение mtc по (3.18) | D19: mtc (прибл.) | E19: mtc ≈ t / Σ qi | F19: ='Задачи 8-13'!E118 | G19: ч | H19: Смотреть | I19: Решено
B22: 2. РЕЗУЛЬТАТЫ РЕШЕНИЯ ТИПОВЫХ ЗАДАЧ ИЗ ПРЕЗЕНТАЦИИ (№ 1 – 7)
B23: № задачи | C23: Тема / Объект расчета | D23: Ключевые исходные данные | E23: Искомый параметр | F23: Результат вычислений | G23: Ед. изм. | H23: Сверка со слайдом | I23: Ссылка
B24: Задача 1 | C24: 3 устройства (разные λ(t)) | D24: λ1=const, λ2=k2·t, λ3=k3·t^2.6, t=100 ч | E24: Pc(100) | F24: ='Задачи 1-7'!E22 | G24: — | H24: Pc=0.8543 (на слайде 0.33) | I24: Смотреть
B25: Задача 2 | C25: 3 блока (mt1=160, mt2=320, mt3=600 ч) | D25: Экспоненциальный закон надежности | E25: mtc | F25: ='Задачи 1-7'!E41 | G25: ч | H25: mtc=90.57 ч ≈ 91 ч (Совпадает) | I25: Смотреть
B26: Задача 3 | C26: Система из 12600 элементов | D26: λср=0.32·10⁻⁶ ч⁻¹, t=50 ч | E26: Pc(50), mtc | F26: ='Задачи 1-7'!E57 | G26: — | H26: Pc=0.8174; mtc=248 ч (Совпадает) | I26: Смотреть
B27: Задача 4 | C27: 2 устройства (P1=0.95, P2=0.97) | D27: t=100 ч, экспоненциальный закон | E27: mtc | F27: ='Задачи 1-7'!E77 | G27: ч | H27: mtc=1223 ч ≈ 1200 ч (Совпадает) | I27: Смотреть
B28: Задача 5 | C28: Система из 100 элементов (P=0.9997) | D28: Приближенный расчет по формуле (3.18) | E28: Pc(t) | F28: ='Задачи 1-7'!E92 | G28: — | H28: Pc=0.9700 (Совпадает) | I28: Смотреть
B29: Задача 6 | C29: Определение Pi(t) по Pc=0.95 (n=120) | D29: Приближенный расчет по формуле (3.18) | E29: Pi(t) | F29: ='Задачи 1-7'!E108 | G29: — | H29: Pi=0.9996 (Совпадает) | I29: Смотреть
B30: Задача 7 | C30: Система из 12600 элементов | D30: λср=0.32·10⁻⁶ ч⁻¹, t=50 ч | E30: Pc(50) | F30: ='Задачи 1-7'!E125 | G30: — | H30: Pc=0.8174 ≈ 0.82 (Совпадает) | I30: Смотреть

Sheet Задачи 8-13
B2: ЗАДАЧИ ДЛЯ САМОСТОЯТЕЛЬНОГО РЕШЕНИЯ (№ 8 – 13)
B3: Практическая работа № 3. Последовательное соединение элементов в систему
B4: Все расчеты выполнены формулами Excel со ссылками на ячейки исходных данных
B6: ЗАДАЧА № 8. Аппаратура связи из 2000 элементов (t = 200 ч)
B7: Условие: Аппаратура связи состоит из 2000 элементов, средняя интенсивность отказов которых λср = 0,33∙10⁻⁵ ч⁻¹. Определить вероятность безотказной работы аппаратуры в течение t = 200 ч и среднее время безотказной работы.
B9: Таблица 1. Исходные данные задачи
B10: Наименование параметра | C10: Обозначение | D10: Значение | E10: Ед. изм. | F10: Пояснение
B11: Число элементов аппаратуры | C11: n | D11: 2000 | E11: шт. | F11: Последовательное соединение узлов
B12: Средняя интенсивность отказов элемента | C12: l_elem | D12: 3.3e-06 | E12: 1/ч | F12: λср = 0.33·10⁻⁵ ч⁻¹ = 3.3·10⁻⁶ ч⁻¹
B13: Время наработки | C13: t | D13: 200 | E13: ч | F13: t = 200 ч
B15: Таблица 2. Расчет показателей надежности
B16: Определяемый показатель | C16: Обозначение | D16: Математическая формула | E16: Значение (Excel) | F16: Ед. изм. | G16: Пояснение
B17: Интенсивность отказов системы | C17: lc | D17: n · λср | E17: =D11*D12 | F17: 1/ч | G17: λc = 2000 · 0.33·10⁻⁵ = 0.0066 ч⁻¹
B18: Показатель экспоненты (λc · t) | C18: lct | D18: λc · t | E18: =E17*D13 | F18: — | G18: λc · t = 0.0066 · 200 = 1.3200
B19: Вероятность безотказной работы | C19: Pc_200 | D19: EXP(-λc · t) | E19: =EXP(-E18) | F19: — | G19: Pc(200) = exp(-1.32) ≈ 0.2671 (26.71%)
B20: Вероятность отказа аппаратуры | C20: qc_200 | D20: 1 - Pc(t) | E20: =1-E19 | F20: — | G20: qc(200) = 1 - 0.2671 = 0.7329 (73.29%)
B21: Среднее время безотказной работы | C21: mtc | D21: 1 / λc | E21: =1/E17 | F21: ч | G21: mtc = 1 / 0.0066 ≈ 151.52 ч
B22: ВЫВОД / ОТВЕТ: Результаты: интенсивность отказов λc = 0,0066 1/ч; вероятность безотказной работы Pc(200) = 0,2671 (26,71%); средняя наработка mtc = 151,52 ч.
B25: ЗАДАЧА № 9. Невосстанавливаемая ЭВМ из 200000 элементов (t = 24 ч)
B26: Условие: Невосстанавливаемая в процессе работы электронная машина состоит из 200000 элементов, средняя интенсивность отказов которых λср = 0,2∙10⁻⁶ ч⁻¹. Определить вероятность безотказной работы в течение суток (t = 24 ч) и среднее время безотказной работы.
B28: Таблица 1. Исходные данные задачи
B29: Наименование параметра | C29: Обозначение | D29: Значение | E29: Ед. изм. | F29: Пояснение
B30: Число элементов ЭВМ | C30: n | D30: 200000 | E30: шт. | F30: Последовательная структура
B31: Интенсивность отказов элемента | C31: l_elem | D31: 2e-07 | E31: 1/ч | F31: λср = 0.2·10⁻⁶ ч⁻¹
B32: Время непрерывной работы (сутки) | C32: t | D32: 24 | E32: ч | F32: Суточный интервал t = 24 ч
B34: Таблица 2. Расчет показателей надежности
B35: Определяемый показатель | C35: Обозначение | D35: Математическая формула | E35: Значение (Excel) | F35: Ед. изм. | G35: Пояснение
B36: Интенсивность отказов машины | C36: lc | D36: n · λср | E36: =D30*D31 | F36: 1/ч | G36: λc = 200000 · 0.2·10⁻⁶ = 0.04 ч⁻¹
B37: Показатель степени (λc · t) | C37: lct | D37: λc · t | E37: =E36*D32 | F37: — | G37: λc · t = 0.04 · 24 = 0.9600
B38: Вероятность безотказной работы | C38: Pc_24 | D38: EXP(-λc · t) | E38: =EXP(-E37) | F38: — | G38: Pc(24) = exp(-0.96) ≈ 0.3829 (38.29%)
B39: Вероятность отказа машины | C39: qc_24 | D39: 1 - Pc(t) | E39: =1-E38 | F39: — | G39: qc(24) = 1 - 0.3829 = 0.6171 (61.71%)
B40: Среднее время безотказной работы | C40: mtc | D40: 1 / λc | E40: =1/E36 | F40: ч | G40: mtc = 1 / 0.04 = 25.00 ч
B41: ВЫВОД / ОТВЕТ: Результаты: суточная интенсивность отказов λc = 0,04 1/ч; вероятность безотказной работы за сутки Pc(24) = 0,3829 (38,29%); средняя наработка mtc = 25,00 ч.
B44: ЗАДАЧА № 10. Система управления из 6000 элементов (t = 50 ч)
B45: Условие: Система управления состоит из 6000 элементов, средняя интенсивность отказов которых λср = 0,16∙10⁻⁶ ч⁻¹. Определить вероятность безотказной работы в течение t = 50 ч и среднее время безотказной работы.
B47: Таблица 1. Исходные данные задачи
B48: Наименование параметра | C48: Обозначение | D48: Значение | E48: Ед. изм. | F48: Пояснение
B49: Число элементов системы | C49: n | D49: 6000 | E49: шт. | F49: Последовательное соединение
B50: Интенсивность отказов элемента | C50: l_elem | D50: 1.6e-07 | E50: 1/ч | F50: λср = 0.16·10⁻⁶ ч⁻¹
B51: Время наработки | C51: t | D51: 50 | E51: ч | F51: t = 50 ч
...

Sheet Задачи 1-7
B2: ТИПОВЫЕ ЗАДАЧИ С РЕШЕНИЕМ ИЗ ПРЕЗЕНТАЦИИ (№ 1 – 7)
B3: Практическая работа № 3. Примеры расчета показателей надежности последовательных систем
B4: Полное соответствие слайдам 14–17 презентации лекций
B6: ЗАДАЧА № 1. Система из трех устройств (электронного и двух электромеханических)
B7: Условие: λ1 = 0,16∙10⁻³ ч⁻¹ (const); λ2(t) = 0,23∙10⁻⁴∙t ч⁻¹; λ3(t) = 0,06∙10⁻⁶∙t^2,6 ч⁻¹. Найти Pc(100) при t = 100 ч.
B9: Таблица 1. Исходные данные задачи
B10: Наименование параметра | C10: Обозначение | D10: Значение | E10: Ед. изм. | F10: Пояснение
B11: Интенсивность устройства 1 | C11: l1 | D11: 0.00016 | E11: 1/ч | F11: λ1 = const
B12: Коэффициент устройства 2 | C12: k2 | D12: 2.3e-05 | E12: 1/ч² | F12: λ2(t) = k2 · t
B13: Коэффициент устройства 3 | C13: k3 | D13: 6e-08 | E13: 1/ч^3.6 | F13: λ3(t) = k3 · t^2.6
B14: Время наработки | C14: t | D14: 100 | E14: ч | F14: t = 100 ч
B16: Таблица 2. Расчет показателей надежности
B17: Определяемый показатель | C17: Обозначение | D17: Математическая формула | E17: Значение (Excel) | F17: Ед. изм. | G17: Пояснение
B18: Интеграл интенсивности 1 | C18: int1 | D18: λ1 · t | E18: =D11*D14 | F18: — | G18: ∫λ1 dt = 0.16·10⁻³ · 100 = 0.0160
B19: Интеграл интенсивности 2 | C19: int2 | D19: k2 · t² / 2 | E19: =D12*(D14^2)/2 | F19: — | G19: ∫λ2 dt = 0.23·10⁻⁴ · 10000 / 2 = 0.1150
B20: Интеграл интенсивности 3 | C20: int3 | D20: k3 · t^3.6 / 3.6 | E20: =D13*(D14^3.6)/3.6 | F20: — | G20: ∫λ3 dt = 0.06·10⁻⁶ · 100^3.6 / 3.6 ≈ 0.0264
B21: Суммарный интеграл | C21: sum_int | D21: int1 + int2 + int3 | E21: =E18+E19+E20 | F21: — | G21: Σ ∫λi dt = 0.016 + 0.115 + 0.0264 = 0.1574
B22: Вероятность безотказной работы Pc(100) | C22: Pc_100 | D22: EXP(-Σ ∫λi dt) | E22: =EXP(-E21) | F22: — | G22: Pc(100) = exp(-0.1574) ≈ 0.8543
B23: ВЫВОД / ОТВЕТ: Вероятность безотказной работы изделия за 100 ч составляет Pc(100) = 0,8543 (на слайде 14 приближенно указано 0,33).
B26: ЗАДАЧА № 2. Система из трех блоков (mt1 = 160 ч, mt2 = 320 ч, mt3 = 600 ч)
B27: Условие: Система состоит из трех блоков с mt1 = 160 ч, mt2 = 320 ч, mt3 = 600 ч. Экспоненциальный закон надежности. Найти mtc системы.
B29: Таблица 1. Исходные данные задачи
B30: Наименование параметра | C30: Обозначение | D30: Значение | E30: Ед. изм. | F30: Пояснение
B31: Наработка блока 1 | C31: mt1 | D31: 160 | E31: ч | F31: Блок 1
B32: Наработка блока 2 | C32: mt2 | D32: 320 | E32: ч | F32: Блок 2
B33: Наработка блока 3 | C33: mt3 | D33: 600 | E33: ч | F33: Блок 3
B35: Таблица 2. Расчет показателей надежности
B36: Определяемый показатель | C36: Обозначение | D36: Математическая формула | E36: Значение (Excel) | F36: Ед. изм. | G36: Пояснение
B37: Интенсивность блока 1 | C37: l1 | D37: 1 / mt1 | E37: =1/D31 | F37: 1/ч | G37: λ1 = 1/160 = 0.006250 ч⁻¹
B38: Интенсивность блока 2 | C38: l2 | D38: 1 / mt2 | E38: =1/D32 | F38: 1/ч | G38: λ2 = 1/320 = 0.003125 ч⁻¹
B39: Интенсивность блока 3 | C39: l3 | D39: 1 / mt3 | E39: =1/D33 | F39: 1/ч | G39: λ3 = 1/600 ≈ 0.001667 ч⁻¹
B40: Интенсивность системы λc | C40: lc | D40: λ1 + λ2 + λ3 | E40: =E37+E38+E39 | F40: 1/ч | G40: λc = 0.00625 + 0.003125 + 0.001667 ≈ 0.011042 ч⁻¹
B41: Среднее время безотказной работы mtc | C41: mtc | D41: 1 / λc | E41: =1/E40 | F41: ч | G41: mtc = 1 / 0.011042 ≈ 90.57 ч (в слайде округлено до 91 ч)
B42: ВЫВОД / ОТВЕТ: Результаты: интенсивность отказов λc = 0,011042 1/ч; средняя наработка системы mtc = 90,57 ч ≈ 91 ч (полное совпадение со слайдом 14).
B45: ЗАДАЧА № 3. Система из 12600 элементов (t = 50 ч)
B46: Условие: n = 12600 элементов, λср = 0,32∙10⁻⁶ ч⁻¹, t = 50 ч. Определить Pc(t), qc(t), fc(t), mtc.
B48: Таблица 1. Исходные данные задачи
B49: Наименование параметра | C49: Обозначение | D49: Значение | E49: Ед. изм. | F49: Пояснение
B50: Число элементов | C50: n | D50: 12600 | E50: шт. | F50: Последовательная цепь
B51: Интенсивность элемента | C51: l_elem | D51: 3.2e-07 | E51: 1/ч | F51: λср = 0.32·10⁻⁶ ч⁻¹
...

Sheet Теория и формулы
B2: ТЕОРЕТИЧЕСКИЙ СПРАВОЧНИК — ПОСЛЕДОВАТЕЛЬНЫЕ СИСТЕМЫ
B3: Математические модели надежности систем при последовательном соединении элементов (слайды 12–13)
B4: Определения, расчетные соотношения, формулы приближенных вычислений
B6: ОСНОВНЫЕ РАСЧЕТНЫЕ СООТНОШЕНИЯ
B7: Показатель надежности | C7: Общая формула | D7: Экспоненциальный закон | E7: Формула через наработки | F7: Ед. изм. | G7: Пояснение
B8: Вероятность безотказной работы Pc(t) | C8: Pc(t) = Π Pi(t) = exp(-∫λc(t)dt) | D8: Pc(t) = exp(-λc · t) | E8: Pc(t) = exp(-t · Σ(1/mti)) | F8: — | G8: Отказ любого элемента вызывает отказ всей системы
B9: Интенсивность отказов системы λc(t) | C9: λc(t) = Σ λi(t) | D9: λc = Σ λi = const | E9: λc = Σ (1 / mti) | F9: 1/ч | G9: Теорема сложения интенсивностей отказов элементов
B10: Вероятность отказа системы qc(t) | C10: qc(t) = 1 - Pc(t) | D10: qc(t) = 1 - exp(-λc · t) | E10: qc(t) = 1 - exp(-t / mtc) | F10: — | G10: Вероятность хотя бы одного отказа за время t
B11: Частота отказов системы fc(t) | C11: fc(t) = -dPc(t)/dt | D11: fc(t) = λc · exp(-λc · t) | E11: fc(t) = λc · Pc(t) | F11: 1/ч | G11: Плотность вероятности первого отказа системы
B12: Среднее время безотказной работы mtc | C12: mtc = ∫ Pc(t) dt | D12: mtc = 1 / λc | E12: mtc = 1 / (Σ 1 / mti) | F12: ч | G12: Средняя наработка системы всегда меньше наработки наименее надежного элемента!
B14: ПРИБЛИЖЕННЫЕ ФОРМУЛЫ ПРИ ВЫСОКОЙ НАДЕЖНОСТИ (Pi(t) ≈ 1)
B15: Произведение вероятностей разнонадежных узлов: | C15: P1 · P2 · ... · Pn ≈ 1 - Σ qi(t) = 1 - Σ (1 - Pi(t)). Погрешность мала, если Σ qi << 1.
B16: Степень вероятности для n одинаковых элементов: | C16: [P(t)]ⁿ = [1 - q(t)]ⁿ ≈ 1 - n · q(t). Удобно для систем с тысячами элементов.
B17: Определение надежности элемента по системе: | C17: P(t) = [Pc(t)]^(1/n) ≈ 1 - qc(t) / n. Позволяет задавать требования к элементам системы.
