Workbook

Sheet Итоговая таблица
B2: СВОДНЫЕ РЕЗУЛЬТАТЫ ПРАКТИЧЕСКОЙ РАБОТЫ № 1
B3: Студент: Гайнетдинов | Вариант / Задания № 6 – 15
B5: Таблица полученных значений показателей надежности:
B6: № задания | C6: Краткое условие | D6: Показатель | E6: Формула | F6: Значение | G6: Размерность
B7: Задание 6 | C7: 100 изделий, за 4000 ч отк. 50, за 4000-4100 отк. 20 | D7: f(4000) | E7: f = Δn/(N·Δt) | F7: ='Решения (№6-15)'!F19 | G7: 1/ч
B8: Задание 6 | C8: 100 изделий, за 4000 ч отк. 50, за 4000-4100 отк. 20 | D8: λ(4000) | E8: λ = Δn/(n(t)·Δt) | F8: ='Решения (№6-15)'!F20 | G8: 1/ч
B9: Задание 7 | C9: 100 изделий, за 4000 ч отк. 50 шт. | D9: p(4000) | E9: p = n(t)/N | F9: ='Решения (№6-15)'!F35 | G9: —
B10: Задание 7 | C10: 100 изделий, за 4000 ч отк. 50 шт. | D10: q(4000) | E10: q = 1 - p | F10: ='Решения (№6-15)'!F36 | G10: —
B11: Задание 8 | C11: 10 гироскопов, за 1000 ч отк. 2, за 1000-1100 отк. 1 | D11: f(1000) | E11: f = Δn/(N·Δt) | F11: ='Решения (№6-15)'!F53 | G11: 1/ч
B12: Задание 8 | C12: 10 гироскопов, за 1000 ч отк. 2, за 1000-1100 отк. 1 | D12: λ(1000) | E12: λ = Δn/(n(t)·Δt) | F12: ='Решения (№6-15)'!F54 | G12: 1/ч
B13: Задание 9 | C13: 1000 ламп, за 3000 ч отк. 80, за 3000-4000 отк. 50 | D13: p(4000) | E13: p = n(4000)/N | F13: ='Решения (№6-15)'!F70 | G13: —
B14: Задание 9 | C14: 1000 ламп, за 3000 ч отк. 80, за 3000-4000 отк. 50 | D14: q(4000) | E14: q = 1 - p | F14: ='Решения (№6-15)'!F71 | G14: —
B15: Задание 10 | C15: 1000 изделий, t=1300 ч (отк. 288), dt=100 ч (отк. 13) | D15: p(1300) | E15: p = n(1300)/N | F15: ='Решения (№6-15)'!F89 | G15: —
B16: Задание 10 | C16: 1000 изделий, t=1400 ч | D16: p(1400) | E16: p = n(1400)/N | F16: ='Решения (№6-15)'!F90 | G16: —
B17: Задание 10 | C17: 1000 изделий, dt=100 ч | D17: f(1300) | E17: f = Δn/(N·dt) | F17: ='Решения (№6-15)'!F91 | G17: 1/ч
B18: Задание 10 | C18: 1000 изделий, dt=100 ч | D18: λ(1300) | E18: λ = Δn/(n·dt) | F18: ='Решения (№6-15)'!F92 | G18: 1/ч
B19: Задание 11 | C19: 45 изделий, t=60 ч (отк. 35), dt=5 ч (отк. 3) | D19: p(60) | E19: p = n(60)/N | F19: ='Решения (№6-15)'!F110 | G19: —
B20: Задание 11 | C20: 45 изделий, t=65 ч | D20: p(65) | E20: p = n(65)/N | F20: ='Решения (№6-15)'!F111 | G20: —
B21: Задание 11 | C21: 45 изделий, dt=5 ч | D21: f(60) | E21: f = Δn/(N·dt) | F21: ='Решения (№6-15)'!F112 | G21: 1/ч
B22: Задание 11 | C22: 45 изделий, dt=5 ч | D22: λ(60) | E22: λ = Δn/(n·dt) | F22: ='Решения (№6-15)'!F113 | G22: 1/ч
B23: Задание 12 | C23: 45 образцов РЭО (интервалы 0-70 ч) | D23: mt* | E23: mt* = Σ(ni·tср)/N | F23: ='Решения (№6-15)'!F130 | G23: ч
B24: Задание 13 | C24: 8 изделий (наработки 560..920 ч) | D24: mt* | E24: mt* = Σti/N | F24: ='Решения (№6-15)'!F148 | G24: ч
B25: Задание 14 | C25: 6 отказов (восстановление 10..30 мин) | D25: mt | E25: mt = Σtв/N | F25: ='Решения (№6-15)'!F165 | G25: мин
B26: Задание 15 | C26: 1000 изделий, t=11000 ч (отк. 410), dt=1000 ч (отк. 40) | D26: p(11000) | E26: p = n(11000)/N | F26: ='Решения (№6-15)'!F183 | G26: —
B27: Задание 15 | C27: 1000 изделий, t=12000 ч | D27: p(12000) | E27: p = n(12000)/N | F27: ='Решения (№6-15)'!F184 | G27: —
B28: Задание 15 | C28: 1000 изделий, dt=1000 ч | D28: f(11000) | E28: f = Δn/(N·dt) | F28: ='Решения (№6-15)'!F185 | G28: 1/ч
B29: Задание 15 | C29: 1000 изделий, dt=1000 ч | D29: λ(11000) | E29: λ = Δn/(n·dt) | F29: ='Решения (№6-15)'!F186 | G29: 1/ч

Sheet Решения (№6-15)
B2: РАСЧЕТНАЯ ЧАСТЬ ПРАКТИЧЕСКОЙ РАБОТЫ № 1 (ЗАДАНИЯ 6 – 15)
B3: Оценка надежности изделий по статистике отказов | Студент: Гайнетдинов
B5: Задание №6. Интенсивность и частота отказов
B6: Текст задания: На испытании N=100 изделий. К t=4000 ч отказало 50 шт. На участке 4000-4100 ч отказало 20 шт. Найти f(4000) и λ(4000).
B8: 1. Исходные параметры
B9: Наименование | C9: Символ | D9: Значение | E9: Размерность
B10: Количество изделий | C10: N | D10: 100 | E10: шт.
B11: Время t | C11: t | D11: 4000 | E11: ч
B12: Число отказов к моменту t | C12: notk | D12: 50 | E12: шт.
B13: Период времени | C13: dt | D13: 100 | E13: ч
B14: Отказов за период | C14: dn | D14: 20 | E14: шт.
B16: 2. Расчетные формулы и вычисления
B17: Искомый показатель | C17: Обозначение | D17: Матем. формула | E17: Формула в Excel | F17: Результат | G17: Ед.
B18: Число исправных к t | C18: n(t) | D18: N - notk | E18: =D10-D12 | F18: =D10-D12 | G18: шт.
B19: Частота отказов | C19: f(4000) | D19: dn / (N · dt) | E19: =D14/(D10*D13) | F19: =D14/(D10*D13) | G19: 1/ч
B20: Интенсивность отказов | C20: λ(4000) | D20: dn / (n(t) · dt) | E20: =D14/(F18*D13) | F20: =D14/(F18*D13) | G20: 1/ч
B21: Итог: f(4000) = 0,002 1/ч, λ(4000) = 0,004 1/ч.
B23: Задание №7. Вероятность безотказной работы и вероятность отказа
B24: Текст задания: На испытании N=100 изделий. К наработке t=4000 ч отказало 50 шт. Найти p(4000) и q(4000).
B26: 1. Исходные параметры
B27: Наименование | C27: Символ | D27: Значение | E27: Размерность
B28: Количество изделий | C28: N | D28: 100 | E28: шт.
B29: Наработка t | C29: t | D29: 4000 | E29: ч
B30: Число отказов | C30: notk | D30: 50 | E30: шт.
B32: 2. Расчетные формулы и вычисления
B33: Искомый показатель | C33: Обозначение | D33: Матем. формула | E33: Формула в Excel | F33: Результат | G33: Ед.
B34: Исправных изделий | C34: n(t) | D34: N - notk | E34: =D28-D30 | F34: =D28-D30 | G34: шт.
B35: Вероятность безотказной работы | C35: p(4000) | D35: n(t) / N | E35: =F34/D28 | F35: =F34/D28 | G35: —
B36: Вероятность отказа | C36: q(4000) | D36: 1 - p | E36: =1-F35 | F36: =1-F35 | G36: —
B37: Итог: p(4000) = 0,5000; q(4000) = 0,5000.
B39: Задание №8. Показатели безотказности гироскопов
B40: Текст задания: За 1000 ч из N=10 гироскопов отказало 2. В интервале 1000-1100 ч отказал еще 1 гироскоп. Найти f(1000) и λ(1000).
B42: 1. Исходные параметры
B43: Наименование | C43: Символ | D43: Значение | E43: Размерность
B44: Число гироскопов | C44: N | D44: 10 | E44: шт.
B45: Время t | C45: t | D45: 1000 | E45: ч
B46: Число отказов к моменту t | C46: notk | D46: 2 | E46: шт.
B47: Шаг по времени | C47: dt | D47: 100 | E47: ч
B48: Отказов за интервал | C48: dn | D48: 1 | E48: шт.
B50: 2. Расчетные формулы и вычисления
...
