Workbook

Sheet Итоговая ведомость
B2: ИТОГОВАЯ ВЕДОМОСТЬ — ПРАКТИЧЕСКАЯ РАБОТА № 3
B3: Студент: Гарифуллин | Вариант / Задания № 8 – 13
B4: Сводная таблица результатов аналитического расчета надежности системы
B6: Сводные числовые результаты расчета последовательных систем:
B7: № задания | C7: Объект расчета | D7: Показатель | E7: Формула | F7: Результат | G7: Ед. изм.
B8: Задание 8 | C8: Аппаратура связи (2000 элементов, t=200 ч) | D8: Pc(200) | E8: Pc = exp(-λc·t) | F8: ='Расчетная часть (№8-13)'!D18 | G8: —
B9: Задание 8 | C9: Аппаратура связи (2000 элементов, t=200 ч) | D9: mtc | E9: mtc = 1 / λc | F9: ='Расчетная часть (№8-13)'!D19 | G9: ч
B10: Задание 9 | C10: ЭВМ из 200000 элементов (сутки) | D10: Pc(24) | E10: Pc = exp(-λc·t) | F10: ='Расчетная часть (№8-13)'!D34 | G10: —
B11: Задание 9 | C11: ЭВМ из 200000 элементов (сутки) | D11: mtc | E11: mtc = 1 / λc | F11: ='Расчетная часть (№8-13)'!D35 | G11: ч
B12: Задание 10 | C12: Система управления (6000 элементов, t=50 ч) | D12: Pc(50) | E12: Pc = exp(-λc·t) | F12: ='Расчетная часть (№8-13)'!D50 | G12: —
B13: Задание 10 | C13: Система управления (6000 элементов, t=50 ч) | D13: mtc | E13: mtc = 1 / λc | F13: ='Расчетная часть (№8-13)'!D51 | G13: ч
B14: Задание 11 | C14: Прибор из 5 узлов | D14: Pc (точная) | E14: Pc = Π Pi | F14: ='Расчетная часть (№8-13)'!D67 | G14: —
B15: Задание 11 | C15: Прибор из 5 узлов | D15: Pc (прибл.) | E15: Pc ≈ 1 - Σ qi | F15: ='Расчетная часть (№8-13)'!D68 | G15: —
B16: Задание 12 | C16: Система из 5 приборов (mti = {83, 220, 280, 400, 700}) | D16: λc | E16: λc = Σ(1/mti) | F16: ='Расчетная часть (№8-13)'!E81 | G16: 1/ч
B17: Задание 12 | C17: Система из 5 приборов (mti = {83, 220, 280, 400, 700}) | D17: mtc | E17: mtc = 1 / λc | F17: ='Расчетная часть (№8-13)'!D85 | G17: ч
B18: Задание 13 | C18: 5 блоков с Pi={0.98..0.985} за 50 ч | D18: mtc | E18: mtc = -t / ln(Pc) | F18: ='Расчетная часть (№8-13)'!D104 | G18: ч

Sheet Расчетная часть (№8-13)
B2: РАСЧЕТНАЯ ЧАСТЬ ПРАКТИЧЕСКОЙ РАБОТЫ № 3 (ЗАДАНИЯ 8 – 13)
B3: Последовательное соединение элементов в систему | Студент: Гарифуллин
B4: Расчет показателей надежности формулами Excel со ссылками на исходные ячейки
B6: Задание 8. Аппаратура связи (2000 элементов, t = 200 ч)
B7: Условие задания: Аппаратура связи: n = 2000 элементов, λср = 0,33∙10⁻⁵ ч⁻¹. Определить Pc(200) и mtc.
B9: 1. Исходные данные:
B10: Параметр | C10: Обозначение | D10: Значение | E10: Размерность
B11: Число элементов | C11: n | D11: 2000 | E11: шт.
B12: Интенсивность λср | C12: l_elem | D12: 3.3e-06 | E12: 1/ч
B13: Время t | C13: t | D13: 200 | E13: ч
B15: 2. Формульный расчет:
B16: Искомый показатель | C16: Матем. формула | D16: Значение в Excel | E16: Размерность
B17: Интенсивность системы λc | C17: n · λср | D17: =D11*D12 | E17: 1/ч
B18: Вероятность безотказной работы | C18: exp(-λc·t) | D18: =EXP(-D17*D13) | E18: —
B19: Среднее время работы системы | C19: 1 / λc | D19: =1/D17 | E19: ч
B20: Ответ: Pc(200) = 0,2671 (26,71%); mtc = 151,52 ч.
B22: Задание 9. ЭВМ из 200000 элементов (сутки, t = 24 ч)
B23: Условие задания: Невосстанавливаемая машина: n = 200000, λср = 0,2∙10⁻⁶ ч⁻¹. Найти Pc(24) и mtc.
B25: 1. Исходные данные:
B26: Параметр | C26: Обозначение | D26: Значение | E26: Размерность
B27: Число элементов | C27: n | D27: 200000 | E27: шт.
B28: Интенсивность λср | C28: l_elem | D28: 2e-07 | E28: 1/ч
B29: Сутки t | C29: t | D29: 24 | E29: ч
B31: 2. Формульный расчет:
B32: Искомый показатель | C32: Матем. формула | D32: Значение в Excel | E32: Размерность
B33: Интенсивность системы λc | C33: n · λср | D33: =D27*D28 | E33: 1/ч
B34: Вероятность безотказной работы | C34: exp(-λc·t) | D34: =EXP(-D33*D29) | E34: —
B35: Среднее время работы ЭВМ | C35: 1 / λc | D35: =1/D33 | E35: ч
B36: Ответ: Pc(24) = 0,3829 (38,29%); mtc = 25,00 ч.
B38: Задание 10. Система управления (6000 элементов, t = 50 ч)
B39: Условие задания: Система управления: n = 6000, λср = 0,16∙10⁻⁶ ч⁻¹. Определить Pc(50) и mtc.
B41: 1. Исходные данные:
B42: Параметр | C42: Обозначение | D42: Значение | E42: Размерность
B43: Число элементов | C43: n | D43: 6000 | E43: шт.
B44: Интенсивность λср | C44: l_elem | D44: 1.6e-07 | E44: 1/ч
B45: Время t | C45: t | D45: 50 | E45: ч
B47: 2. Формульный расчет:
B48: Искомый показатель | C48: Матем. формула | D48: Значение в Excel | E48: Размерность
B49: Интенсивность системы λc | C49: n · λср | D49: =D43*D44 | E49: 1/ч
B50: Вероятность безотказной работы | C50: exp(-λc·t) | D50: =EXP(-D49*D45) | E50: —
...
