Workbook

Sheet Итоговая ведомость
B2: ИТОГОВАЯ ВЕДОМОСТЬ РАСЧЕТА НАДЕЖНОСТИ (ПРАКТИКА № 4)
B3: Сводная таблица параметров и контрольных значений по задачам постоянного резервирования
B4: Студент: Гарифуллин Камиль Рамилевич | Группа: ЭАС-414С
B6: Выполнил студент: | D6: Гарифуллин Камиль Рамилевич
B7: Группа / Специальность: | D7: ЭАС-414С / Электропривод и автоматика
B8: Дисциплина: | D8: Надежность автоматизированных систем (НАС)
B9: Тема работы: | D9: Расчет надежности системы с постоянным резервированием (Слайды 19-28)
B11: № Задачи | C11: Объект исследования | D11: Определяемый показатель | E11: Формула связи | F11: Численный результат | G11: Ед. изм. | H11: Оценка
B12: № 4 | C12: Трехблочная система без резерва | D12: Pc_нр(100) | E12: ='Расчетная часть (№4-14)'!E14 | F12: — | G12: Соответствует
B13: № 4 | C13: Трехблочная система с дублированием | D13: Pc_дубл(100) | E13: ='Расчетная часть (№4-14)'!E15 | F13: — | G13: Соответствует
B14: № 5 | C14: Сложная система 4.3 (надежность) | D14: Pc(100) | E14: ='Расчетная часть (№4-14)'!E26 | F14: — | G14: Соответствует
B15: № 5 | C15: Сложная система 4.3 (наработка) | D15: mtc | E15: ='Расчетная часть (№4-14)'!E27 | F15: ч | G15: Соответствует
B16: № 6 | C16: Радиопередатчик с дублированием (наработка) | D16: mtc | E16: ='Расчетная часть (№4-14)'!E40 | F16: ч | G16: Соответствует
B17: № 6 | C17: Радиопередатчик с дублированием (надежность) | D17: Pc(100) | E17: ='Расчетная часть (№4-14)'!E41 | F17: — | G17: Соответствует
B18: № 7 | C18: Дублированная цепь 4.4 (наработка mtc) | D18: mtc | E18: ='Расчетная часть (№4-14)'!E54 | F18: ч | G18: Соответствует
B19: № 7 | C19: Дублированная цепь 4.4 (интенсивность λc) | D19: λc(100) | E19: ='Расчетная часть (№4-14)'!E55 | F19: 1/ч | G19: Соответствует
B20: № 8 | C20: Трехблочная цепь без резерва | D20: Pc_нр(100) | E20: ='Расчетная часть (№4-14)'!E67 | F20: — | G20: Соответствует
B21: № 8 | C21: Трехблочная цепь с дублированием | D21: Pc_дубл(100) | E21: ='Расчетная часть (№4-14)'!E68 | F21: — | G21: Соответствует
B22: № 9 | C22: Тройное резервирование 4.5 (надежность) | D22: Pc(100) | E22: ='Расчетная часть (№4-14)'!E81 | F22: — | G22: Соответствует
B23: № 9 | C23: Тройное резервирование 4.5 (наработка) | D23: mtc | E23: ='Расчетная часть (№4-14)'!E82 | F23: ч | G23: Соответствует
B24: № 9 | C24: Тройное резервирование 4.5 (интенсивность) | D24: λc(100) | E24: ='Расчетная часть (№4-14)'!E84 | F24: 1/ч | G24: Соответствует
B25: № 10 | C25: Телевизионный канал (средняя наработка) | D25: mtc | E25: ='Расчетная часть (№4-14)'!E95 | F25: ч | G25: Соответствует
B26: № 10 | C26: Телевизионный канал (надежность t=50 ч) | D26: Pc(50) | E26: ='Расчетная часть (№4-14)'!E96 | F26: — | G26: Соответствует
B27: № 11 | C27: Дублированная цепь двух блоков (интенсивность) | D27: λc(50) | E27: ='Расчетная часть (№4-14)'!E109 | F27: 1/ч | G27: Соответствует
B28: № 12 | C28: Система 4000 элементов (λдоп без резерва) | D28: λдоп_а | E28: ='Расчетная часть (№4-14)'!E120 | F28: 1/ч | G28: Соответствует
B29: № 12 | C29: Система 4000 элементов (λдоп с дублированием) | D29: λдоп_б | E29: ='Расчетная часть (№4-14)'!E122 | F29: 1/ч | G29: Соответствует
B30: № 13 | C30: Требуемая надежность блока: без резерва | D30: Pбл_а | E30: ='Расчетная часть (№4-14)'!E132 | F30: — | G30: Соответствует
B31: № 13 | C31: Требуемая надежность блока: общее дублирование | D31: Pбл_б | E31: ='Расчетная часть (№4-14)'!E134 | F31: — | G31: Соответствует
B32: № 13 | C32: Требуемая надежность блока: раздельное дублирование | D32: Pбл_в | E32: ='Расчетная часть (№4-14)'!E136 | F32: — | G32: Соответствует
B33: № 14 | C33: Двухблочный вычислитель (надежность t=20 ч) | D33: Pc(20) | E33: ='Расчетная часть (№4-14)'!E148 | F33: — | G33: Соответствует
B34: № 14 | C34: Двухблочный вычислитель (наработка mtc) | D34: mtc | E34: ='Расчетная часть (№4-14)'!E147 | F34: ч | G34: Соответствует

Sheet Расчетная часть (№4-14)
B2: ИНЖЕНЕРНЫЙ РАСЧЕТ НАДЕЖНОСТИ РЕЗЕРВИРОВАННЫХ СИСТЕМ (№ 4 – 14)
B3: Практическая работа № 4. Вариант Гарифуллина К.Р. (группа ЭАС-414С)
B4: Математическое моделирование систем с постоянным резервированием в среде MS Excel
B6: ЗАДАЧА № 4. СИСТЕМА ИЗ ТРЕХ БЛОКОВ С ОБЩИМ ДУБЛИРОВАНИЕМ
B7: Постановка задачи: Технологическая система из 3 блоков (λ1=4*10^-4, λ2=2.5*10^-4, λ3=3*10^-4 1/ч). Расчет Pc при t=100 ч без резерва и с общим дублированием.
B8: Показатель / Этап расчета | C8: Символ | D8: Математическая модель | E8: Численное значение | F8: Ед. | G8: Характеристика параметра
B9: Интенсивность отказа блока 1 | C9: λ1 | D9: Исходные данные | E9: 0.0004 | F9: 1/ч | G9: Блок 1 (4.0*10^-4)
B10: Интенсивность отказа блока 2 | C10: λ2 | D10: Исходные данные | E10: 0.00025 | F10: 1/ч | G10: Блок 2 (2.5*10^-4)
B11: Интенсивность отказа блока 3 | C11: λ3 | D11: Исходные данные | E11: 0.0003 | F11: 1/ч | G11: Блок 3 (3.0*10^-4)
B12: Время непрерывной работы | C12: t | D12: Исходные данные | E12: 100 | F12: ч | G12: Контрольный период
B13: Интенсивность основной цепи | C13: λ0 | D13: λ1 + λ2 + λ3 | E13: =E9+E10+E11 | F13: 1/ч | G13: Суммарная интенсивность цепи
B14: а) Надежность без резервирования | C14: Pc_нр | D14: EXP(-λ0 * t) | E14: =EXP(-E13*E12) | F14: — | G14: Pc(100) = e^-0.095 ≈ 0.90938
B15: б) Надежность с общим дублированием | C15: Pc_дубл | D15: 1 - (1 - EXP(-λ0*t))^2 | E15: =1-(1-EXP(-E13*E12))^2 | F15: — | G15: Pc(100) = 2e^-λ0t - e^-2λ0t
B16: Инженерное заключение: Общее дублирование повышает надежность с 90.94% до 99.18%, снижая вероятность отказа почти в 11 раз.
B19: ЗАДАЧА № 5. АНАЛИЗ СЛОЖНОЙ СТРУКТУРЫ С РЕЗЕРВИРОВАНИЕМ (РИС. 4.3)
B20: Постановка задачи: Логическая схема 4.3: часть I (две ветви по 4 блока λ) соединена последовательно с частью II (1 блок λ). Найти Pc(t), mtc, fc(t), λc(t).
B21: Показатель / Этап расчета | C21: Символ | D21: Математическая модель | E21: Численное значение | F21: Ед. | G21: Характеристика параметра
B22: Блоков в параллельной цепи | C22: n1 | D22: Схема 4.3 | E22: 4 | F22: шт. | G22: Последовательно в ветви
B23: Базовая интенсивность блока | C23: λ | D23: Принято | E23: 0.0001 | F23: 1/ч | G23: λ = 1.0*10^-4 1/ч
B24: Период наработки | C24: t | D24: Принято | E24: 100 | F24: ч | G24: Контрольная наработка
B25: Интенсивность параллельной ветви | C25: λ_ветвь | D25: 4 * λ | E25: =4*E23 | F25: 1/ч | G25: Интенсивность одной цепи 4λ
B26: Вероятность системы Pc(t) | C26: Pc(t) | D26: 2*EXP(-5*λ*t) - EXP(-9*λ*t) | E26: =2*EXP(-5*E23*E24)-EXP(-9*E23*E24) | F26: — | G26: Pc(t) = 2e^-5λt - e^-9λt
B27: Средняя наработка системы mtc | C27: mtc | D27: 13 / (45 * λ) | E27: =13/(45*E23) | F27: ч | G27: mtc = 13/(45λ) = 2888.89 ч
B28: Частота отказов системы fc(t) | C28: fc(t) | D28: 10*λ*EXP(-5*λ*t) - 9*λ*EXP(-9*λ*t) | E28: =10*E23*EXP(-5*E23*E24)-9*E23*EXP(-9*E23*E24) | F28: 1/ч | G28: fc(t) = -dPc/dt
B29: Интенсивность отказов системы λc(t) | C29: λc(t) | D29: fc(t) / Pc(t) | E29: =E28/E26 | F29: 1/ч | G29: λc(t) = λ(10-9e^-4λt)/(2-e^-4λt)
B30: Инженерное заключение: Аналитические модели: Pc(t) = 2e^-5λt - e^-9λt, mtc = 13/(45λ), fc(t) = 10λe^-5λt - 9λe^-9λt.
B33: ЗАДАЧА № 6. ОБЩЕЕ ПОСТОЯННОЕ ДУБЛИРОВАНИЕ РАДИОПЕРЕДАТЧИКА
B34: Постановка задачи: Радиопередатчик из 3 каскадов (λ=5*10^-4 1/ч), общее дублирование. Найти Pc(t), mtc, fc(t), λc(t).
B35: Показатель / Этап расчета | C35: Символ | D35: Математическая модель | E35: Численное значение | F35: Ед. | G35: Характеристика параметра
B36: Число каскадов | C36: n | D36: Исходные данные | E36: 3 | F36: шт. | G36: Последовательные узлы
B37: Интенсивность каскада | C37: λ | D37: Исходные данные | E37: 0.0005 | F37: 1/ч | G37: λ = 5.0*10^-4 1/ч
B38: Контрольное время | C38: t | D38: Принято | E38: 100 | F38: ч | G38: t = 100 ч
B39: Интенсивность цепи передатчика | C39: λ0 | D39: n * λ | E39: =E36*E37 | F39: 1/ч | G39: λ0 = 0.0015 1/ч
B40: Средняя наработка mtc | C40: mtc | D40: 1.5 / λ0 | E40: =1.5/E39 | F40: ч | G40: mtc = 1.5 / 0.0015 = 1000 ч
B41: Вероятность работы Pc(t) | C41: Pc(t) | D41: 1 - (1 - EXP(-λ0*t))^2 | E41: =1-(1-EXP(-E39*E38))^2 | F41: — | G41: Pc(100) = 0.98060
B42: Частота отказов fc(t) | C42: fc(t) | D42: 2*λ0*EXP(-λ0*t)*(1-EXP(-λ0*t)) | E42: =2*E39*EXP(-E39*E38)*(1-EXP(-E39*E38)) | F42: 1/ч | G42: fc(100) ≈ 0.000360 1/ч
B43: Интенсивность отказов λc(t) | C43: λc(t) | D43: fc(t) / Pc(t) | E43: =E42/E41 | F43: 1/ч | G43: λc(100) ≈ 0.000367 1/ч
B44: Инженерное заключение: mtc = 1000 ч; Pc(t) = 2e^-0.0015t - e^-0.003t. Вероятность безотказной работы на интервале 100 ч составляет 98.06%.
B47: ЗАДАЧА № 7. ИНТЕНСИВНОСТЬ ОТКАЗОВ СХЕМЫ 4.4
B48: Постановка задачи: Схема 4.4: две ветви по 4 блока λ. Нагруженный резерв. Определить аналитическое выражение интенсивности отказов λc(t).
...

Sheet Справочные формулы
B2: СПРАВОЧНИК МАТЕМАТИЧЕСКИХ МОДЕЛЕЙ НАДЕЖНОСТИ (ПРАКТИКА № 4)
B3: Аналитические зависимости теории постоянного резервирования (Раздел 4.1)
B4: Для инженерных расчетов систем автоматики и управления
B6: 1. Постоянное резервирование (нагруженный резерв)
B7: Физический смысл | C7: Резервные элементы подключены постоянно и работают в таком же режиме, как и основные.
B8: Вероятность отказа | C8: qc(t) = Произведение(1 - Pj(t)) = (1 - P(t))^(m+1) при равнонадежных цепях.
B9: Вероятность безотказной работы | C9: Pc(t) = 1 - (1 - P(t))^(m+1). При m=1 (дублирование): Pc(t) = 2P(t) - P^2(t).
B10: Экспоненциальная модель | C10: Pc(t) = 2*exp(-λ0*t) - exp(-2*λ0*t), где λ0 - интенсивность цепи.
B12: 2. Количественные показатели надежности
B13: Средняя наработка mtc (m=1) | C13: mtc = 1.5 * T0 = 1.5 / λ0 (выигрыш в 1.5 раза относительно цепи).
B14: Средняя наработка mtc (кратность m) | C14: mtc = (1/λ0) * (1 + 1/2 + ... + 1/(m+1)).
B15: Частота отказов fc(t) | C15: fc(t) = 2*λ0*exp(-λ0*t)*(1 - exp(-λ0*t)).
B16: Интенсивность отказов λc(t) | C16: λc(t) = 2*λ0*(1 - exp(-λ0*t)) / (2 - exp(-λ0*t)). При t=0 λc=0.
B18: 3. Эффективность резервирования
B19: Общее резервирование | C19: Резервируется вся система в целом: Pобщ = 1 - (1 - Pсист)^2.
B20: Раздельное резервирование | C20: Резервируется каждый блок отдельно: Pразд = [1 - (1 - Pбл)^2]^n.
B21: Сравнение | C21: Раздельное резервирование существенно надежнее общего при одинаковом расходе аппаратуры.
