Workbook

Sheet Сводка и Ответы
B2: ПРАКТИЧЕСКАЯ РАБОТА № 2 — СВОДНЫЕ РЕЗУЛЬТАТЫ
B3: Аналитическое определение количественных характеристик надежности изделия (экспоненциальный закон надежности)
B4: Дисциплина: Надежность автоматизированных систем (НАС) | Преподаватель: Ризванов | Выполнил: Студент Гайнанов Д.И. (группа ЭАС-414С)
B6: 1. РЕЗУЛЬТАТЫ РЕШЕНИЯ ЗАДАЧ ДЛЯ САМОСТОЯТЕЛЬНОГО РЕШЕНИЯ (№ 6 – 12)
B7: № задачи | C7: Краткое условие задачи | D7: Определяемые параметры | E7: Расчетная формула (математическая) | F7: Результат вычислений | G7: Ед. изм. | H7: Ссылка на лист решения | I7: Статус
B8: Задача 6 | C8: L1=460 ч, t=800 ч. Найти интенсивность отказов λ | D8: λ(800) | E8: λ = 1 / L1 | F8: ='Задачи 6-12'!E16 | G8: 1/ч | H8: Перейти к решению | I8: Решено
B9: Задача 6 (2) | C9: Та же задача, вероятность безотказной работы P(800) | D9: P(800) | E9: P(t) = exp(-λ · t) | F9: ='Задачи 6-12'!E18 | G9: — | H9: Перейти к решению | I9: Решено
B10: Задача 6 (3) | C10: Та же задача, частота отказов f(800) | D10: f(800) | E10: f(t) = λ · P(t) | F10: ='Задачи 6-12'!E20 | G10: 1/ч | H10: Перейти к решению | I10: Решено
B11: Задача 7 | C11: n=6000 элементов, λср=0.2·10⁻⁶ ч⁻¹, T=50 ч. Найти Pc(50) | D11: Pc(50) | E11: Pc(T) = exp(-n · λср · T) | F11: ='Задачи 6-12'!E37 | G11: — | H11: Перейти к решению | I11: Решено
B12: Задача 7 (2) | C12: Та же задача, среднее время безотказной работы mtc | D12: mtc | E12: mtc = 1 / (n · λср) | F12: ='Задачи 6-12'!E40 | G12: ч | H12: Перейти к решению | I12: Решено
B13: Задача 8 | C13: n=5000 элементов, λср=0.3·10⁻⁶ ч⁻¹, T=120 ч. Найти Pc(120) | D13: Pc(120) | E13: Pc(T) = exp(-n · λср · T) | F13: ='Задачи 6-12'!E57 | G13: — | H13: Перейти к решению | I13: Решено
B14: Задача 8 (2) | C14: Та же задача, среднее время безотказной работы mtc | D14: mtc | E14: mtc = 1 / (n · λср) | F14: ='Задачи 6-12'!E60 | G14: ч | H14: Перейти к решению | I14: Решено
B15: Задача 9 | C15: ЭВМ из n=200000 элементов, λср=0.3·10⁻⁶ ч⁻¹, сутки (t=24 ч) | D15: Pc(24) | E15: Pc(24) = exp(-n · λср · 24) | F15: ='Задачи 6-12'!E77 | G15: — | H15: Перейти к решению | I15: Решено
B16: Задача 9 (2) | C16: Та же задача, среднее время безотказной работы ЭВМ | D16: mtc | E16: mtc = 1 / (n · λср) | F16: ='Задачи 6-12'!E80 | G16: ч | H16: Перейти к решению | I16: Решено
B17: Задача 10 | C17: n=12600, λср=0.32·10⁻⁶ ч⁻¹, t=50 ч. Вероятность Pc(50) | D17: Pc(50) | E17: Pc(t) = exp(-λc · t) | F17: ='Задачи 6-12'!E97 | G17: — | H17: Перейти к решению | I17: Решено
B18: Задача 10 (2) | C18: Та же задача, вероятность отказа системы qc(50) | D18: qc(50) | E18: qc(t) = 1 - Pc(t) | F18: ='Задачи 6-12'!E98 | G18: — | H18: Перейти к решению | I18: Решено
B19: Задача 10 (3) | C19: Та же задача, частота отказов fc(50) | D19: fc(50) | E19: fc(t) = λc · Pc(t) | F19: ='Задачи 6-12'!E99 | G19: 1/ч | H19: Перейти к решению | I19: Решено
B20: Задача 10 (4) | C20: Та же задача, средняя наработка системы mtc | D20: mtc | E20: mtc = 1 / λc | F20: ='Задачи 6-12'!E100 | G20: ч | H20: Перейти к решению | I20: Решено
B21: Задача 11 | C21: Прибор с λ=0.1·10⁻⁶ ч⁻¹, t=180 ч. Вероятность p(180) | D21: p(180) | E21: p(t) = exp(-λ · t) | F21: ='Задачи 6-12'!E115 | G21: — | H21: Перейти к решению | I21: Решено
B22: Задача 11 (2) | C22: Та же задача, вероятность отказа прибора q(180) | D22: q(180) | E22: q(t) = 1 - p(t) | F22: ='Задачи 6-12'!E116 | G22: — | H22: Перейти к решению | I22: Решено
B23: Задача 11 (3) | C23: Та же задача, частота отказов прибора f(180) | D23: f(180) | E23: f(t) = λ · p(t) | F23: ='Задачи 6-12'!E117 | G23: 1/ч | H23: Перейти к решению | I23: Решено
B24: Задача 11 (4) | C24: Та же задача, среднее время безотказной работы mt | D24: mt | E24: mt = 1 / λ | F24: ='Задачи 6-12'!E118 | G24: ч | H24: Перейти к решению | I24: Решено
B25: Задача 12 | C25: Система из 5 приборов (mti={83, 220, 280, 400, 700} ч) | D25: λc | E25: λc = Σ (1 / mti) | F25: ='Задачи 6-12'!F132 | G25: 1/ч | H25: Перейти к решению | I25: Решено
B26: Задача 12 (2) | C26: Та же задача, среднее время безотказной работы mtc | D26: mtc | E26: mtc = 1 / λc | F26: ='Задачи 6-12'!E137 | G26: ч | H26: Перейти к решению | I26: Решено
B29: 2. РЕЗУЛЬТАТЫ РЕШЕНИЯ ТИПОВЫХ ЗАДАЧ ИЗ ПРЕЗЕНТАЦИИ (№ 1 – 5)
B30: № задачи | C30: Тема / Объект расчета | D30: Ключевые исходные данные | E30: Искомый параметр | F30: Результат вычислений | G30: Ед. изм. | H30: Сверка со слайдом | I30: Ссылка
B31: Задача 1 | C31: Автоматический регулятор | D31: L1=640 ч, t=120 ч | E31: P(120), λ, f(120) | F31: ='Задачи 1-5'!E18 | G31: — | H31: P=0.83; λ=1.56·10⁻³; f=1.29·10⁻³ (Совпадает) | I31: Смотреть
B32: Задача 2 | C32: Система из N одинаковых элементов | D32: P=0.99, N1=1000, N2=100 | E32: Pc(1000), Pc(100) | F32: ='Задачи 1-5'!E35 | G32: — | H32: Pc(1000)=0.432·10⁻⁴; Pc(100)=0.366 (Совпадает) | I32: Смотреть
B33: Задача 3 | C33: Система управления | D33: n=6000, λср=0.2·10⁻⁶, T=50 ч | E33: Pc(50), mtc | F33: ='Задачи 1-5'!E54 | G33: ч | H33: mtc=833.3 ч; Pc(50)=0.9418 (в слайде опечатка 0.994) | I33: Смотреть
B34: Задача 4 | C34: Система из 11000 элементов | D34: n=11000, λср=0.12·10⁻⁶, t=80 ч | E34: Pc(80), mtc, fc(80) | F34: ='Задачи 1-5'!E74 | G34: ч | H34: mtc=758 ч; Pc=0.8998 (на слайде ≈0.82) | I34: Смотреть
B35: Задача 5 | C35: Элемент (экспоненциальный закон) | D35: λ=2.5·10⁻⁵ ч⁻¹, t=1000 ч | E35: p(1000), q, f, mt | F35: ='Задачи 1-5'!E89 | G35: — | H35: p=0.9753; q=0.0247; f=2.439·10⁻⁵; mt=40000 (Совпадает) | I35: Смотреть

Sheet Задачи 6-12
B2: ЗАДАЧИ ДЛЯ САМОСТОЯТЕЛЬНОГО РЕШЕНИЯ (№ 6 – 12)
B3: Практическая работа № 2. Аналитическое определение количественных характеристик надежности изделия
B4: Все расчеты выполнены формулами Excel со ссылками на ячейки исходных данных
B6: ЗАДАЧА № 6. Расчет показателей надежности системы при L1 = 460 ч (t = 800 ч)
B7: Условие: Средняя наработка до отказа L1 системы равна 460 часов. Для экспоненциального закона надежности определить вероятность безотказной работы, частоту отказов и интенсивность отказов за 800 часов работы системы.
B9: Таблица 1. Исходные данные задачи
B10: Наименование параметра | C10: Обозначение | D10: Значение | E10: Ед. изм. | F10: Пояснение
B11: Средняя наработка до отказа | C11: L1 | D11: 460 | E11: ч | F11: L1 = mt = 460 ч
B12: Время работы (наработка) | C12: t | D12: 800 | E12: ч | F12: Момент времени t = 800 ч
B14: Таблица 2. Расчет показателей надежности
B15: Определяемый показатель | C15: Обозначение | D15: Математическая формула | E15: Значение (формула Excel) | F15: Ед. изм. | G15: Пояснение к результату
B16: Интенсивность отказов | C16: l_800 | D16: 1 / L1 | E16: =1/D11 | F16: 1/ч | G16: λ = const = 1 / 460 ≈ 0.002174 ч⁻¹
B17: Показатель экспоненты (λ · t) | C17: lt | D17: λ · t | E17: =E16*D12 | F17: — | G17: λ · t = 800 / 460 ≈ 1.73913
B18: Вероятность безотказной работы | C18: P_800 | D18: EXP(-λ · t) | E18: =EXP(-E17) | F18: — | G18: P(800) = exp(-1.73913) ≈ 0.1757 (17.57%)
B19: Вероятность отказа (доп.) | C19: q_800 | D19: 1 - P(t) | E19: =1-E18 | F19: — | G19: q(800) = 1 - 0.1757 = 0.8243 (82.43%)
B20: Частота отказов системы | C20: f_800 | D20: λ · P(t) | E20: =E16*E18 | F20: 1/ч | G20: f(800) = 0.002174 · 0.1757 ≈ 0.000382 ч⁻¹
B21: ВЫВОД / ОТВЕТ: При t = 800 ч: интенсивность отказов λ = 0,002174 1/ч (2,17·10⁻³ ч⁻¹); вероятность безотказной работы P(800) = 0,1757 (17,57%); частота отказов f(800) = 0,000382 1/ч (3,82·10⁻⁴ ч⁻¹).
B24: ЗАДАЧА № 7. Надежность системы из 6000 последовательных элементов (t = 50 ч)
B25: Условие: Система управления состоит из 6000 элементов, соединенных последовательно, средняя интенсивность отказов которых λср(t) = 0,2∙10⁻⁶ ч⁻¹. Необходимо определить вероятность безотказной работы в течение Т = 50 ч и среднее время безотказной работы системы.
B27: Таблица 1. Исходные данные задачи
B28: Наименование параметра | C28: Обозначение | D28: Значение | E28: Ед. изм. | F28: Пояснение
B29: Число элементов в системе | C29: n | D29: 6000 | E29: шт. | F29: Количество последовательных элементов
B30: Средняя интенсивность отказов элемента | C30: l_elem | D30: 2e-07 | E30: 1/ч | F30: λср = 0.2·10⁻⁶ ч⁻¹ = 2·10⁻⁷ ч⁻¹
B31: Время непрерывной работы | C31: T | D31: 50 | E31: ч | F31: Период испытаний T = 50 ч
B33: Таблица 2. Расчет показателей надежности
B34: Определяемый показатель | C34: Обозначение | D34: Математическая формула | E34: Значение (формула Excel) | F34: Ед. изм. | G34: Пояснение к результату
B35: Интенсивность отказов системы | C35: lc | D35: n · λср | E35: =D29*D30 | F35: 1/ч | G35: λc = 6000 · 0.2·10⁻⁶ = 0.0012 ч⁻¹ (1.2·10⁻³ ч⁻¹)
B36: Показатель экспоненты (λc · T) | C36: lcT | D36: λc · T | E36: =E35*D31 | F36: — | G36: λc · T = 0.0012 · 50 = 0.0600
B37: Вероятность безотказной работы системы | C37: Pc_50 | D37: EXP(-λc · T) | E37: =EXP(-E36) | F37: — | G37: Pc(50) = exp(-0.06) ≈ 0.9418 (94.18%)
B38: Вероятность отказа системы (доп.) | C38: qc_50 | D38: 1 - Pc(T) | E38: =1-E37 | F38: — | G38: qc(50) = 1 - 0.9418 = 0.0582 (5.82%)
B39: Частота отказов системы (доп.) | C39: fc_50 | D39: λc · Pc(T) | E39: =E35*E37 | F39: 1/ч | G39: fc(50) = 0.0012 · 0.9418 ≈ 0.001130 ч⁻¹
B40: Среднее время безотказной работы системы | C40: mtc | D40: 1 / λc | E40: =1/E35 | F40: ч | G40: mtc = 1 / 0.0012 = 833.33 ч
B41: ВЫВОД / ОТВЕТ: Для системы из 6000 элементов: вероятность безотказной работы за 50 ч равна Pc(50) = 0,9418 (94,18%); среднее время безотказной работы системы mtc = 833,33 ч (интенсивность отказов λc = 1,2·10⁻³ ч⁻¹).
B44: ЗАДАЧА № 8. Надежность системы из 5000 последовательных элементов (t = 120 ч)
B45: Условие: Система управления состоит из 5000 элементов, соединенных последовательно, средняя интенсивность отказов которых λср(t) = 0,3∙10⁻⁶ ч⁻¹. Необходимо определить вероятность безотказной работы в течение Т = 120 ч и среднее время безотказной работы системы.
B47: Таблица 1. Исходные данные задачи
B48: Наименование параметра | C48: Обозначение | D48: Значение | E48: Ед. изм. | F48: Пояснение
B49: Число элементов в системе | C49: n | D49: 5000 | E49: шт. | F49: Количество последовательных элементов
B50: Средняя интенсивность отказов элемента | C50: l_elem | D50: 3e-07 | E50: 1/ч | F50: λср = 0.3·10⁻⁶ ч⁻¹ = 3·10⁻⁷ ч⁻¹
B51: Время непрерывной работы | C51: T | D51: 120 | E51: ч | F51: Период испытаний T = 120 ч
...

Sheet Задачи 1-5
B2: ТИПОВЫЕ ЗАДАЧИ С РЕШЕНИЕМ ИЗ ПРЕЗЕНТАЦИИ (№ 1 – 5)
B3: Практическая работа № 2. Аналитическое определение количественных характеристик надежности изделия
B4: Полное соответствие слайдам 8–10 презентации лекций
B6: ЗАДАЧА № 1. Автоматический регулятор (L1 = 640 ч, t = 120 ч)
B7: Условие: Средняя наработка до отказа L1 автоматического регулятора равна 640 часов. Предполагается, что справедлив экспоненциальный закон надежности. Определить вероятность безотказной работы, частоту отказов и интенсивность отказов за 120 часов работы системы.
B9: Таблица 1. Исходные данные задачи
B10: Наименование параметра | C10: Обозначение | D10: Значение | E10: Ед. изм. | F10: Пояснение
B11: Средняя наработка до отказа | C11: L1 | D11: 640 | E11: ч | F11: L1 = 640 ч
B12: Время наработки | C12: t | D12: 120 | E12: ч | F12: Момент времени t = 120 ч
B14: Таблица 2. Расчет показателей надежности
B15: Определяемый показатель | C15: Обозначение | D15: Математическая формула | E15: Значение (формула Excel) | F15: Ед. изм. | G15: Пояснение к результату
B16: Интенсивность отказов | C16: l_120 | D16: 1 / L1 | E16: =1/D11 | F16: 1/ч | G16: λ = const = 1 / 640 ≈ 0.001563 ч⁻¹ (1.56·10⁻³ ч⁻¹)
B17: Показатель экспоненты (λ · t) | C17: lt | D17: λ · t | E17: =E16*D12 | F17: — | G17: λ · t = 120 / 640 = 0.1875
B18: Вероятность безотказной работы | C18: P_120 | D18: EXP(-λ · t) | E18: =EXP(-E17) | F18: — | G18: P(120) = exp(-0.1875) ≈ 0.8290 (в слайде округлено до 0.83)
B19: Частота отказов регулятора | C19: f_120 | D19: λ · P(t) | E19: =E16*E18 | F19: 1/ч | G19: f(120) = 0.001563 · 0.8290 ≈ 0.001295 ч⁻¹ (1.29·10⁻³ ч⁻¹)
B20: ВЫВОД / ОТВЕТ: При t = 120 ч: интенсивность отказов λ = 1,56·10⁻³ 1/ч; вероятность безотказной работы P(120) = 0,8290 ≈ 0,83; частота отказов f(120) = 1,29·10⁻³ 1/ч (полное совпадение со слайдом 8).
B23: ЗАДАЧА № 2. Надежность системы из 1000 и 100 элементов при P(t) = 0,99
B24: Условие: Система состоит из 1000 элементов с высокой вероятностью безотказной работы P(t) = 0,99. Определить надежность всей системы. Определить надежность этой системы, если число элементов – 100?
B26: Таблица 1. Исходные данные задачи
B27: Наименование параметра | C27: Обозначение | D27: Значение | E27: Ед. изм. | F27: Пояснение
B28: Вероятность безотказной работы элемента | C28: P_el | D28: 0.99 | E28: — | F28: P(t) = 0.99 для каждого элемента
B29: Число элементов в первой конфигурации | C29: N1 | D29: 1000 | E29: шт. | F29: N1 = 1000 элементов
B30: Число элементов во второй конфигурации | C30: N2 | D30: 100 | E30: шт. | F30: N2 = 100 элементов
B32: Таблица 2. Расчет показателей надежности
B33: Определяемый показатель | C33: Обозначение | D33: Математическая формула | E33: Значение (формула Excel) | F33: Ед. изм. | G33: Пояснение к результату
B34: Надежность системы при N = 1000 | C34: Pc_1000 | D34: P_el ^ N1 | E34: =D28^D29 | F34: — | G34: Pc = 0.99¹⁰⁰⁰ ≈ 0.00004317 (0.432·10⁻⁴ по слайду)
B35: Надежность системы при N = 100 | C35: Pc_100 | D35: P_el ^ N2 | E35: =D28^D30 | F35: — | G35: Pc = 0.99¹⁰⁰ ≈ 0.36603 (0.366 по слайду)
B36: ВЫВОД / ОТВЕТ: При N = 1000 элементов: Pc(t) = 0,432·10⁻⁴ (система крайне ненадежна из-за большого числа элементов); при N = 100 элементов: Pc(t) = 0,366 (36,6%). Полное совпадение со слайдом 8.
B39: ЗАДАЧА № 3. Система управления из 6000 элементов (T = 50 ч)
B40: Условие: Система управления состоит из 6000 элементов, соединенных последовательно, средняя интенсивность отказов которых λср(t) = 0,2∙10⁻⁶ ч⁻¹. Необходимо определить вероятность безотказной работы Pc(t) в течение Т = 50 ч и среднее время безотказной работы системы mtc.
B42: Таблица 1. Исходные данные задачи
B43: Наименование параметра | C43: Обозначение | D43: Значение | E43: Ед. изм. | F43: Пояснение
B44: Число элементов | C44: n | D44: 6000 | E44: шт. | F44: Последовательное соединение
B45: Интенсивность отказов элемента | C45: l_elem | D45: 2e-07 | E45: 1/ч | F45: λср = 0.2·10⁻⁶ ч⁻¹
B46: Время работы | C46: T | D46: 50 | E46: ч | F46: T = 50 ч
B48: Таблица 2. Расчет показателей надежности
B49: Определяемый показатель | C49: Обозначение | D49: Математическая формула | E49: Значение (формула Excel) | F49: Ед. изм. | G49: Пояснение к результату
B50: Интенсивность отказов системы | C50: lc | D50: n · λср | E50: =D44*D45 | F50: 1/ч | G50: λc = 6000 · 0.2·10⁻⁶ = 0.0012 ч⁻¹ (1.2·10⁻³ ч⁻¹)
B51: Показатель экспоненты (λc · T) | C51: lcT | D51: λc · T | E51: =E50*D46 | F51: — | G51: λc · T = 0.0012 · 50 = 0.0600 (на слайде опечатка 0.006)
B52: Точная вероятность безотказной работы | C52: Pc_50 | D52: EXP(-λc · T) | E52: =EXP(-E51) | F52: — | G52: Pc(50) = exp(-0.06) ≈ 0.9418 (94.18%)
...

Sheet Теория и формулы
B2: ТЕОРЕТИЧЕСКИЙ СПРАВОЧНИК — АНАЛИТИЧЕСКАЯ НАДЕЖНОСТЬ
B3: Аналитическое определение количественных характеристик надежности изделия (ГОСТ 27.002 и тема 2)
B4: Определения, обозначения, математические формулы и физический смысл
B6: ОСНОВНЫЕ АНАЛИТИЧЕСКИЕ ХАРАКТЕРИСТИКИ НАДЕЖНОСТИ
B7: Показатель надежности | C7: Обозначение | D7: Общая формула | E7: Формула при эксп. законе | F7: Ед. изм. | G7: Физический смысл и пояснение
B8: Вероятность безотказной работы | C8: p(t) | D8: p(t) = exp(-∫λ(t)dt) = 1 - ∫f(t)dt | E8: p(t) = e^(-λ·t) | F8: — | G8: Вероятность того, что в пределах заданной наработки t отказ объекта не возникнет
B9: Вероятность отказа изделия | C9: q(t) | D9: q(t) = 1 - p(t) | E9: q(t) = 1 - e^(-λ·t) | F9: — | G9: Вероятность того, что объект откажет хотя бы один раз за время от 0 до t
B10: Частота отказов (плотность) | C10: f(t) | D10: f(t) = -dp(t)/dt = dq(t)/dt | E10: f(t) = λ · e^(-λ·t) = λ · p(t) | F10: 1/ч | G10: Плотность вероятности возникновения отказа невосстанавливаемого объекта в момент t
B11: Интенсивность отказов | C11: λ(t) | D11: λ(t) = f(t) / p(t) = -(1/p)·dp/dt | E11: λ(t) = λ = const | F11: 1/ч | G11: Условная плотность вероятности отказа объекта в момент t при условии безотказной работы до t
B12: Средняя наработка до отказа | C12: mt | D12: mt = ∫ p(t) dt (от 0 до ∞) | E12: mt = 1 / λ | F12: ч | G12: Математическое ожидание времени безотказной работы объекта
B14: ОСОБЕННОСТИ ЭКСПОНЕНЦИАЛЬНОГО ЗАКОНА И СИСТЕМНОЙ НАДЕЖНОСТИ
B15: Свойство отсутствия последействия (старения): | C15: P(t + τ | t) = P(τ) = exp(-λ · τ). Объект не изнашивается и не стареет; надежность зависит только от длительности предстоящей работы.
B16: Постоянство интенсивности отказов: | C16: λ(t) = λ = const на всем периоде нормальной эксплуатации изделия (участок II кривой интенсивности отказов).
B17: Связь средней наработки и интенсивности: | C17: mt = 1 / λ <=> λ = 1 / mt. Если средняя наработка известна, интенсивность отказов находится обратным делением.
B18: Последовательное соединение n элементов: | C18: λc = Σ λi (теорема сложения интенсивностей); для одинаковых элементов: λc = n · λср.
B19: Вероятность безотказной работы системы: | C19: Pc(t) = Π Pi(t) = exp(-λc · t) = exp(-Σ λi · t); для одинаковых элементов: Pc(t) = [P(t)]ⁿ = exp(-n · λср · t).
B20: Средняя наработка последовательной системы: | C20: mtc = 1 / λc = 1 / (Σ 1 / mti). Средняя наработка системы всегда меньше средней наработки самого ненадежного элемента!
