Workbook

Sheet Итоговая таблица
B2: СВОДНЫЕ РЕЗУЛЬТАТЫ ПРАКТИЧЕСКОЙ РАБОТЫ № 2
B3: Студент: Гайнетдинов | Вариант / Задания № 6 – 12
B5: Таблица итоговых ответов по аналитическому расчету надежности:
B6: № задачи | C6: Краткое условие | D6: Параметр | E6: Формула | F6: Результат | G6: Ед. изм.
B7: Задание 6 | C7: L1=460 ч, t=800 ч. Интенсивность отказов | D7: λ(800) | E7: λ = 1 / L1 | F7: ='Решения (№6-12)'!E15 | G7: 1/ч
B8: Задание 6 | C8: L1=460 ч, t=800 ч. Вероятность безотказной работы | D8: P(800) | E8: P = exp(-λ·t) | F8: ='Решения (№6-12)'!E16 | G8: —
B9: Задание 6 | C9: L1=460 ч, t=800 ч. Частота отказов | D9: f(800) | E9: f = λ · P(t) | F9: ='Решения (№6-12)'!E17 | G9: 1/ч
B10: Задание 7 | C10: 6000 элементов, λср=0.2·10⁻⁶ ч⁻¹, T=50 ч | D10: Pc(50) | E10: Pc = exp(-λc·T) | F10: ='Решения (№6-12)'!E32 | G10: —
B11: Задание 7 | C11: 6000 элементов, λср=0.2·10⁻⁶ ч⁻¹, T=50 ч | D11: mtc | E11: mtc = 1 / λc | F11: ='Решения (№6-12)'!E33 | G11: ч
B12: Задание 8 | C12: 5000 элементов, λср=0.3·10⁻⁶ ч⁻¹, T=120 ч | D12: Pc(120) | E12: Pc = exp(-λc·T) | F12: ='Решения (№6-12)'!E48 | G12: —
B13: Задание 8 | C13: 5000 элементов, λср=0.3·10⁻⁶ ч⁻¹, T=120 ч | D13: mtc | E13: mtc = 1 / λc | F13: ='Решения (№6-12)'!E49 | G13: ч
B14: Задание 9 | C14: 200000 элементов, λср=0.3·10⁻⁶ ч⁻¹, сутки (t=24 ч) | D14: Pc(24) | E14: Pc = exp(-λc·t) | F14: ='Решения (№6-12)'!E64 | G14: —
B15: Задание 9 | C15: 200000 элементов, λср=0.3·10⁻⁶ ч⁻¹, сутки (t=24 ч) | D15: mtc | E15: mtc = 1 / λc | F15: ='Решения (№6-12)'!E65 | G15: ч
B16: Задание 10 | C16: 12600 элементов, λср=0.32·10⁻⁶ ч⁻¹, t=50 ч | D16: Pc(50) | E16: Pc = exp(-λc·t) | F16: ='Решения (№6-12)'!E80 | G16: —
B17: Задание 10 | C17: 12600 элементов, λср=0.32·10⁻⁶ ч⁻¹, t=50 ч | D17: qc(50) | E17: qc = 1 - Pc | F17: ='Решения (№6-12)'!E81 | G17: —
B18: Задание 10 | C18: 12600 элементов, λср=0.32·10⁻⁶ ч⁻¹, t=50 ч | D18: fc(50) | E18: fc = λc · Pc | F18: ='Решения (№6-12)'!E82 | G18: 1/ч
B19: Задание 10 | C19: 12600 элементов, λср=0.32·10⁻⁶ ч⁻¹, t=50 ч | D19: mtc | E19: mtc = 1 / λc | F19: ='Решения (№6-12)'!E83 | G19: ч
B20: Задание 11 | C20: Прибор с λ=0.1·10⁻⁶ ч⁻¹, t=180 ч | D20: p(180) | E20: p = exp(-λ·t) | F20: ='Решения (№6-12)'!E96 | G20: —
B21: Задание 11 | C21: Прибор с λ=0.1·10⁻⁶ ч⁻¹, t=180 ч | D21: q(180) | E21: q = 1 - p | F21: ='Решения (№6-12)'!E97 | G21: —
B22: Задание 11 | C22: Прибор с λ=0.1·10⁻⁶ ч⁻¹, t=180 ч | D22: f(180) | E22: f = λ · p | F22: ='Решения (№6-12)'!E98 | G22: 1/ч
B23: Задание 11 | C23: Прибор с λ=0.1·10⁻⁶ ч⁻¹, t=180 ч | D23: mt | E23: mt = 1 / λ | F23: ='Решения (№6-12)'!E99 | G23: ч
B24: Задание 12 | C24: Система из 5 приборов (mti = {83, 220, 280, 400, 700}) | D24: λc | E24: λc = Σ (1/mti) | F24: ='Решения (№6-12)'!E112 | G24: 1/ч
B25: Задание 12 | C25: Система из 5 приборов (mti = {83, 220, 280, 400, 700}) | D25: mtc | E25: mtc = 1 / λc | F25: ='Решения (№6-12)'!E116 | G25: ч

Sheet Решения (№6-12)
B2: РАСЧЕТНАЯ ЧАСТЬ ПРАКТИЧЕСКОЙ РАБОТЫ № 2 (ЗАДАНИЯ 6 – 12)
B3: Аналитическая оценка показателей надежности | Студент: Гайнетдинов
B5: Задание 6. Расчет λ(t), P(t), f(t) при L1 = 460 ч (t = 800 ч)
B6: Текст задания: Средняя наработка до отказа L1 системы равна 460 ч. Для экспоненциального закона надежности определить P(t), f(t) и λ(t) за 800 ч работы системы.
B8: 1. Исходные параметры
B9: Наименование | C9: Символ | D9: Значение | E9: Размерность
B10: Средняя наработка L1 | C10: L1 | D10: 460 | E10: ч
B11: Период эксплуатации t | C11: t | D11: 800 | E11: ч
B13: 2. Аналитический расчет характеристик
B14: Искомый показатель | C14: Матем. формула | D14: Формула в Excel | E14: Значение | F14: Размерность
B15: Интенсивность отказов λ | C15: 1 / L1 | D15: =1/D10 | E15: =1/D10 | F15: 1/ч
B16: Вероятность безотказной работы P | C16: exp(-λ·t) | D16: =EXP(-E15*D11) | E16: =EXP(-E15*D11) | F16: —
B17: Частота отказов f | C17: λ · P(t) | D17: =E15*E16 | E17: =E15*E16 | F17: 1/ч
B18: Вывод: При t = 800 ч: λ = 0,002174 1/ч, P(800) = 0,1757, f(800) = 0,000382 1/ч.
B20: Задание 7. Система управления из 6000 элементов (T = 50 ч)
B21: Текст задания: Система управления состоит из 6000 последовательных элементов с λср = 0,2∙10⁻⁶ ч⁻¹. Определить Pc(50) и mtc.
B23: 1. Исходные параметры
B24: Наименование | C24: Символ | D24: Значение | E24: Размерность
B25: Количество элементов n | C25: n | D25: 6000 | E25: шт.
B26: Интенсивность элемента λср | C26: l_elem | D26: 2e-07 | E26: 1/ч
B27: Время T | C27: T | D27: 50 | E27: ч
B29: 2. Аналитический расчет характеристик
B30: Искомый показатель | C30: Матем. формула | D30: Формула в Excel | E30: Значение | F30: Размерность
B31: Интенсивность отказов системы λc | C31: n · λср | D31: =D25*D26 | E31: =D25*D26 | F31: 1/ч
B32: Вероятность безотказной работы Pc | C32: exp(-λc·T) | D32: =EXP(-E31*D27) | E32: =EXP(-E31*D27) | F32: —
B33: Среднее время работы системы mtc | C33: 1 / λc | D33: =1/E31 | E33: =1/E31 | F33: ч
B34: Вывод: Pc(50) = 0,9418 (94,18%); средняя наработка mtc = 833,33 ч.
B36: Задание 8. Система управления из 5000 элементов (T = 120 ч)
B37: Текст задания: Система управления состоит из 5000 последовательных элементов с λср = 0,3∙10⁻⁶ ч⁻¹. Определить Pc(120) и mtc.
B39: 1. Исходные параметры
B40: Наименование | C40: Символ | D40: Значение | E40: Размерность
B41: Количество элементов n | C41: n | D41: 5000 | E41: шт.
B42: Интенсивность элемента λср | C42: l_elem | D42: 3e-07 | E42: 1/ч
B43: Время T | C43: T | D43: 120 | E43: ч
B45: 2. Аналитический расчет характеристик
B46: Искомый показатель | C46: Матем. формула | D46: Формула в Excel | E46: Значение | F46: Размерность
B47: Интенсивность отказов системы λc | C47: n · λср | D47: =D41*D42 | E47: =D41*D42 | F47: 1/ч
B48: Вероятность безотказной работы Pc | C48: exp(-λc·T) | D48: =EXP(-E47*D43) | E48: =EXP(-E47*D43) | F48: —
B49: Среднее время работы системы mtc | C49: 1 / λc | D49: =1/E47 | E49: =1/E47 | F49: ч
B50: Вывод: Pc(120) = 0,8353 (83,53%); средняя наработка mtc = 666,67 ч.
...
